Workbook

Sheet Từ vựng HSK2
A1: LUYỆN TẬP TỪ VỰNG HSK 2 (HSK 3.0 — 772 từ)
A2: Nhập chữ Hán giản thể hoặc Pinyin (có/không dấu thanh) vào cột B — chỉ cần sửa các ô màu vàng.
A3: Tổng số câu | B3: Số câu đã làm đúng ✅ | C3: Số câu sai ❌ | D3: Tỷ lệ hoàn thành (%)
A4: =COUNTIF($A$8:$A$1007,"?*") -> 772 | B4: =COUNTIF($C$8:$C$1007,"✅") -> 0 | C4: =COUNTIF($C$8:$C$1007,"❌") -> 0 | D4: =IF(A4=0,0,B4/A4) -> 0
A5: Tiến độ | B5: =REPT("█",ROUND(D4*20,0))&REPT("░",20-ROUND(D4*20,0)) -> ░░░░░░░░░░░░░░░░░░░░ | C5: =IF(B4+C4=0,"Độ chính xác: –","Độ chính xác: "&TEXT(B4/(B4+C4),"0%")) -> Độ chính xác: – | D5: Không
D6: ▲ Hiện gợi ý (Có/Không)
A7: Ý nghĩa | B7: Ô người học nhập | C7: Kết quả | D7: Gợi ý | F7: norm có dấu | G7: norm không dấu
A8: =IF(Data_HSK2!E2="","",Data_HSK2!E2) -> à, nhé, nhỉ (trợ từ ngữ khí) | C8: =IF(OR(A8="",TRIM(B8)=""),"",IF(OR(ISNUMBER(FIND("|"&F8&"|",Data_HSK2!G2)),AND(F8=G8,ISNUMBER(FIND("|"&G8&"|",Data_HSK2!H2)))),"✅","❌")) | D8: =IF(OR(A8="",$D$5<>"Có"),"",Data_HSK2!B2&" ("&Data_HSK2!C2&")") | F8: =IF(TRIM(B8)="","",SUBSTITUTE(SUBSTITUTE(SUBSTITUTE(SUBSTITUTE(SUBSTITUTE(SUBSTITUTE(SUBSTITUTE(SUBSTITUTE(SUBSTITUTE(SUBSTITUTE(SUBSTITUTE(SUBSTITUTE(SUBSTITUTE(SUBSTITUTE(SUBSTITUTE(SUBSTITUTE(LOWER(TRIM(B8))," ",""),"'",""),"’",""),"·",""),"/",""),"-",""),"(",""),")",""),"（",""),"）",""),"ü","v"),";","|"),"；","|"),",","|"),"，","|"),"、","|")) | G8: =SUBSTITUTE(SUBSTITUTE(SUBSTITUTE(SUBSTITUTE(SUBSTITUTE(SUBSTITUTE(SUBSTITUTE(SUBSTITUTE(SUBSTITUTE(SUBSTITUTE(SUBSTITUTE(SUBSTITUTE(SUBSTITUTE(SUBSTITUTE(SUBSTITUTE(SUBSTITUTE(SUBSTITUTE(SUBSTITUTE(SUBSTITUTE(SUBSTITUTE(SUBSTITUTE(SUBSTITUTE(SUBSTITUTE(SUBSTITUTE(F8,"ā","a"),"á","a"),"ǎ","a"),"à","a"),"ē","e"),"é","e"),"ě","e"),"è","e"),"ī","i"),"í","i"),"ǐ","i"),"ì","i"),"ō","o"),"ó","o"),"ǒ","o"),"ò","o"),"ū","u"),"ú","u"),"ǔ","u"),"ù","u"),"ǖ","v"),"ǘ","v"),"ǚ","v"),"ǜ","v")
A9: =IF(Data_HSK2!E3="","",Data_HSK2!E3) -> tình yêu (tình cảm lứa đôi) | C9: =IF(OR(A9="",TRIM(B9)=""),"",IF(OR(ISNUMBER(FIND("|"&F9&"|",Data_HSK2!G3)),AND(F9=G9,ISNUMBER(FIND("|"&G9&"|",Data_HSK2!H3)))),"✅","❌")) | D9: =IF(OR(A9="",$D$5<>"Có"),"",Data_HSK2!B3&" ("&Data_HSK2!C3&")") | F9: =IF(TRIM(B9)="","",SUBSTITUTE(SUBSTITUTE(SUBSTITUTE(SUBSTITUTE(SUBSTITUTE(SUBSTITUTE(SUBSTITUTE(SUBSTITUTE(SUBSTITUTE(SUBSTITUTE(SUBSTITUTE(SUBSTITUTE(SUBSTITUTE(SUBSTITUTE(SUBSTITUTE(SUBSTITUTE(LOWER(TRIM(B9))," ",""),"'",""),"’",""),"·",""),"/",""),"-",""),"(",""),")",""),"（",""),"）",""),"ü","v"),";","|"),"；","|"),",","|"),"，","|"),"、","|")) | G9: =SUBSTITUTE(SUBSTITUTE(SUBSTITUTE(SUBSTITUTE(SUBSTITUTE(SUBSTITUTE(SUBSTITUTE(SUBSTITUTE(SUBSTITUTE(SUBSTITUTE(SUBSTITUTE(SUBSTITUTE(SUBSTITUTE(SUBSTITUTE(SUBSTITUTE(SUBSTITUTE(SUBSTITUTE(SUBSTITUTE(SUBSTITUTE(SUBSTITUTE(SUBSTITUTE(SUBSTITUTE(SUBSTITUTE(SUBSTITUTE(F9,"ā","a"),"á","a"),"ǎ","a"),"à","a"),"ē","e"),"é","e"),"ě","e"),"è","e"),"ī","i"),"í","i"),"ǐ","i"),"ì","i"),"ō","o"),"ó","o"),"ǒ","o"),"ò","o"),"ū","u"),"ú","u"),"ǔ","u"),"ù","u"),"ǖ","v"),"ǘ","v"),"ǚ","v"),"ǜ","v")
A10: =IF(Data_HSK2!E4="","",Data_HSK2!E4) -> vợ hoặc chồng, người yêu | C10: =IF(OR(A10="",TRIM(B10)=""),"",IF(OR(ISNUMBER(FIND("|"&F10&"|",Data_HSK2!G4)),AND(F10=G10,ISNUMBER(FIND("|"&G10&"|",Data_HSK2!H4)))),"✅","❌")) | D10: =IF(OR(A10="",$D$5<>"Có"),"",Data_HSK2!B4&" ("&Data_HSK2!C4&")") | F10: =IF(TRIM(B10)="","",SUBSTITUTE(SUBSTITUTE(SUBSTITUTE(SUBSTITUTE(SUBSTITUTE(SUBSTITUTE(SUBSTITUTE(SUBSTITUTE(SUBSTITUTE(SUBSTITUTE(SUBSTITUTE(SUBSTITUTE(SUBSTITUTE(SUBSTITUTE(SUBSTITUTE(SUBSTITUTE(LOWER(TRIM(B10))," ",""),"'",""),"’",""),"·",""),"/",""),"-",""),"(",""),")",""),"（",""),"）",""),"ü","v"),";","|"),"；","|"),",","|"),"，","|"),"、","|")) | G10: =SUBSTITUTE(SUBSTITUTE(SUBSTITUTE(SUBSTITUTE(SUBSTITUTE(SUBSTITUTE(SUBSTITUTE(SUBSTITUTE(SUBSTITUTE(SUBSTITUTE(SUBSTITUTE(SUBSTITUTE(SUBSTITUTE(SUBSTITUTE(SUBSTITUTE(SUBSTITUTE(SUBSTITUTE(SUBSTITUTE(SUBSTITUTE(SUBSTITUTE(SUBSTITUTE(SUBSTITUTE(SUBSTITUTE(SUBSTITUTE(F10,"ā","a"),"á","a"),"ǎ","a"),"à","a"),"ē","e"),"é","e"),"ě","e"),"è","e"),"ī","i"),"í","i"),"ǐ","i"),"ì","i"),"ō","o"),"ó","o"),"ǒ","o"),"ò","o"),"ū","u"),"ú","u"),"ǔ","u"),"ù","u"),"ǖ","v"),"ǘ","v"),"ǚ","v"),"ǜ","v")
A11: =IF(Data_HSK2!E5="","",Data_HSK2!E5) -> yên tĩnh | C11: =IF(OR(A11="",TRIM(B11)=""),"",IF(OR(ISNUMBER(FIND("|"&F11&"|",Data_HSK2!G5)),AND(F11=G11,ISNUMBER(FIND("|"&G11&"|",Data_HSK2!H5)))),"✅","❌")) | D11: =IF(OR(A11="",$D$5<>"Có"),"",Data_HSK2!B5&" ("&Data_HSK2!C5&")") | F11: =IF(TRIM(B11)="","",SUBSTITUTE(SUBSTITUTE(SUBSTITUTE(SUBSTITUTE(SUBSTITUTE(SUBSTITUTE(SUBSTITUTE(SUBSTITUTE(SUBSTITUTE(SUBSTITUTE(SUBSTITUTE(SUBSTITUTE(SUBSTITUTE(SUBSTITUTE(SUBSTITUTE(SUBSTITUTE(LOWER(TRIM(B11))," ",""),"'",""),"’",""),"·",""),"/",""),"-",""),"(",""),")",""),"（",""),"）",""),"ü","v"),";","|"),"；","|"),",","|"),"，","|"),"、","|")) | G11: =SUBSTITUTE(SUBSTITUTE(SUBSTITUTE(SUBSTITUTE(SUBSTITUTE(SUBSTITUTE(SUBSTITUTE(SUBSTITUTE(SUBSTITUTE(SUBSTITUTE(SUBSTITUTE(SUBSTITUTE(SUBSTITUTE(SUBSTITUTE(SUBSTITUTE(SUBSTITUTE(SUBSTITUTE(SUBSTITUTE(SUBSTITUTE(SUBSTITUTE(SUBSTITUTE(SUBSTITUTE(SUBSTITUTE(SUBSTITUTE(F11,"ā","a"),"á","a"),"ǎ","a"),"à","a"),"ē","e"),"é","e"),"ě","e"),"è","e"),"ī","i"),"í","i"),"ǐ","i"),"ì","i"),"ō","o"),"ó","o"),"ǒ","o"),"ò","o"),"ū","u"),"ú","u"),"ǔ","u"),"ù","u"),"ǖ","v"),"ǘ","v"),"ǚ","v"),"ǜ","v")
A12: =IF(Data_HSK2!E6="","",Data_HSK2!E6) -> an toàn | C12: =IF(OR(A12="",TRIM(B12)=""),"",IF(OR(ISNUMBER(FIND("|"&F12&"|",Data_HSK2!G6)),AND(F12=G12,ISNUMBER(FIND("|"&G12&"|",Data_HSK2!H6)))),"✅","❌")) | D12: =IF(OR(A12="",$D$5<>"Có"),"",Data_HSK2!B6&" ("&Data_HSK2!C6&")") | F12: =IF(TRIM(B12)="","",SUBSTITUTE(SUBSTITUTE(SUBSTITUTE(SUBSTITUTE(SUBSTITUTE(SUBSTITUTE(SUBSTITUTE(SUBSTITUTE(SUBSTITUTE(SUBSTITUTE(SUBSTITUTE(SUBSTITUTE(SUBSTITUTE(SUBSTITUTE(SUBSTITUTE(SUBSTITUTE(LOWER(TRIM(B12))," ",""),"'",""),"’",""),"·",""),"/",""),"-",""),"(",""),")",""),"（",""),"）",""),"ü","v"),";","|"),"；","|"),",","|"),"，","|"),"、","|")) | G12: =SUBSTITUTE(SUBSTITUTE(SUBSTITUTE(SUBSTITUTE(SUBSTITUTE(SUBSTITUTE(SUBSTITUTE(SUBSTITUTE(SUBSTITUTE(SUBSTITUTE(SUBSTITUTE(SUBSTITUTE(SUBSTITUTE(SUBSTITUTE(SUBSTITUTE(SUBSTITUTE(SUBSTITUTE(SUBSTITUTE(SUBSTITUTE(SUBSTITUTE(SUBSTITUTE(SUBSTITUTE(SUBSTITUTE(SUBSTITUTE(F12,"ā","a"),"á","a"),"ǎ","a"),"à","a"),"ē","e"),"é","e"),"ě","e"),"è","e"),"ī","i"),"í","i"),"ǐ","i"),"ì","i"),"ō","o"),"ó","o"),"ǒ","o"),"ò","o"),"ū","u"),"ú","u"),"ǔ","u"),"ù","u"),"ǖ","v"),"ǘ","v"),"ǚ","v"),"ǜ","v")
A13: =IF(Data_HSK2!E7="","",Data_HSK2!E7) -> màu trắng | C13: =IF(OR(A13="",TRIM(B13)=""),"",IF(OR(ISNUMBER(FIND("|"&F13&"|",Data_HSK2!G7)),AND(F13=G13,ISNUMBER(FIND("|"&G13&"|",Data_HSK2!H7)))),"✅","❌")) | D13: =IF(OR(A13="",$D$5<>"Có"),"",Data_HSK2!B7&" ("&Data_HSK2!C7&")") | F13: =IF(TRIM(B13)="","",SUBSTITUTE(SUBSTITUTE(SUBSTITUTE(SUBSTITUTE(SUBSTITUTE(SUBSTITUTE(SUBSTITUTE(SUBSTITUTE(SUBSTITUTE(SUBSTITUTE(SUBSTITUTE(SUBSTITUTE(SUBSTITUTE(SUBSTITUTE(SUBSTITUTE(SUBSTITUTE(LOWER(TRIM(B13))," ",""),"'",""),"’",""),"·",""),"/",""),"-",""),"(",""),")",""),"（",""),"）",""),"ü","v"),";","|"),"；","|"),",","|"),"，","|"),"、","|")) | G13: =SUBSTITUTE(SUBSTITUTE(SUBSTITUTE(SUBSTITUTE(SUBSTITUTE(SUBSTITUTE(SUBSTITUTE(SUBSTITUTE(SUBSTITUTE(SUBSTITUTE(SUBSTITUTE(SUBSTITUTE(SUBSTITUTE(SUBSTITUTE(SUBSTITUTE(SUBSTITUTE(SUBSTITUTE(SUBSTITUTE(SUBSTITUTE(SUBSTITUTE(SUBSTITUTE(SUBSTITUTE(SUBSTITUTE(SUBSTITUTE(F13,"ā","a"),"á","a"),"ǎ","a"),"à","a"),"ē","e"),"é","e"),"ě","e"),"è","e"),"ī","i"),"í","i"),"ǐ","i"),"ì","i"),"ō","o"),"ó","o"),"ǒ","o"),"ò","o"),"ū","u"),"ú","u"),"ǔ","u"),"ù","u"),"ǖ","v"),"ǘ","v"),"ǚ","v"),"ǜ","v")
A14: =IF(Data_HSK2!E8="","",Data_HSK2!E8) -> lớp trưởng | C14: =IF(OR(A14="",TRIM(B14)=""),"",IF(OR(ISNUMBER(FIND("|"&F14&"|",Data_HSK2!G8)),AND(F14=G14,ISNUMBER(FIND("|"&G14&"|",Data_HSK2!H8)))),"✅","❌")) | D14: =IF(OR(A14="",$D$5<>"Có"),"",Data_HSK2!B8&" ("&Data_HSK2!C8&")") | F14: =IF(TRIM(B14)="","",SUBSTITUTE(SUBSTITUTE(SUBSTITUTE(SUBSTITUTE(SUBSTITUTE(SUBSTITUTE(SUBSTITUTE(SUBSTITUTE(SUBSTITUTE(SUBSTITUTE(SUBSTITUTE(SUBSTITUTE(SUBSTITUTE(SUBSTITUTE(SUBSTITUTE(SUBSTITUTE(LOWER(TRIM(B14))," ",""),"'",""),"’",""),"·",""),"/",""),"-",""),"(",""),")",""),"（",""),"）",""),"ü","v"),";","|"),"；","|"),",","|"),"，","|"),"、","|")) | G14: =SUBSTITUTE(SUBSTITUTE(SUBSTITUTE(SUBSTITUTE(SUBSTITUTE(SUBSTITUTE(SUBSTITUTE(SUBSTITUTE(SUBSTITUTE(SUBSTITUTE(SUBSTITUTE(SUBSTITUTE(SUBSTITUTE(SUBSTITUTE(SUBSTITUTE(SUBSTITUTE(SUBSTITUTE(SUBSTITUTE(SUBSTITUTE(SUBSTITUTE(SUBSTITUTE(SUBSTITUTE(SUBSTITUTE(SUBSTITUTE(F14,"ā","a"),"á","a"),"ǎ","a"),"à","a"),"ē","e"),"é","e"),"ě","e"),"è","e"),"ī","i"),"í","i"),"ǐ","i"),"ì","i"),"ō","o"),"ó","o"),"ǒ","o"),"ò","o"),"ū","u"),"ú","u"),"ǔ","u"),"ù","u"),"ǖ","v"),"ǘ","v"),"ǚ","v"),"ǜ","v")
A15: =IF(Data_HSK2!E9="","",Data_HSK2!E9) -> làm, xử lý (công việc) | C15: =IF(OR(A15="",TRIM(B15)=""),"",IF(OR(ISNUMBER(FIND("|"&F15&"|",Data_HSK2!G9)),AND(F15=G15,ISNUMBER(FIND("|"&G15&"|",Data_HSK2!H9)))),"✅","❌")) | D15: =IF(OR(A15="",$D$5<>"Có"),"",Data_HSK2!B9&" ("&Data_HSK2!C9&")") | F15: =IF(TRIM(B15)="","",SUBSTITUTE(SUBSTITUTE(SUBSTITUTE(SUBSTITUTE(SUBSTITUTE(SUBSTITUTE(SUBSTITUTE(SUBSTITUTE(SUBSTITUTE(SUBSTITUTE(SUBSTITUTE(SUBSTITUTE(SUBSTITUTE(SUBSTITUTE(SUBSTITUTE(SUBSTITUTE(LOWER(TRIM(B15))," ",""),"'",""),"’",""),"·",""),"/",""),"-",""),"(",""),")",""),"（",""),"）",""),"ü","v"),";","|"),"；","|"),",","|"),"，","|"),"、","|")) | G15: =SUBSTITUTE(SUBSTITUTE(SUBSTITUTE(SUBSTITUTE(SUBSTITUTE(SUBSTITUTE(SUBSTITUTE(SUBSTITUTE(SUBSTITUTE(SUBSTITUTE(SUBSTITUTE(SUBSTITUTE(SUBSTITUTE(SUBSTITUTE(SUBSTITUTE(SUBSTITUTE(SUBSTITUTE(SUBSTITUTE(SUBSTITUTE(SUBSTITUTE(SUBSTITUTE(SUBSTITUTE(SUBSTITUTE(SUBSTITUTE(F15,"ā","a"),"á","a"),"ǎ","a"),"à","a"),"ē","e"),"é","e"),"ě","e"),"è","e"),"ī","i"),"í","i"),"ǐ","i"),"ì","i"),"ō","o"),"ó","o"),"ǒ","o"),"ò","o"),"ū","u"),"ú","u"),"ǔ","u"),"ù","u"),"ǖ","v"),"ǘ","v"),"ǚ","v"),"ǜ","v")
A16: =IF(Data_HSK2!E10="","",Data_HSK2!E10) -> biện pháp, cách | C16: =IF(OR(A16="",TRIM(B16)=""),"",IF(OR(ISNUMBER(FIND("|"&F16&"|",Data_HSK2!G10)),AND(F16=G16,ISNUMBER(FIND("|"&G16&"|",Data_HSK2!H10)))),"✅","❌")) | D16: =IF(OR(A16="",$D$5<>"Có"),"",Data_HSK2!B10&" ("&Data_HSK2!C10&")") | F16: =IF(TRIM(B16)="","",SUBSTITUTE(SUBSTITUTE(SUBSTITUTE(SUBSTITUTE(SUBSTITUTE(SUBSTITUTE(SUBSTITUTE(SUBSTITUTE(SUBSTITUTE(SUBSTITUTE(SUBSTITUTE(SUBSTITUTE(SUBSTITUTE(SUBSTITUTE(SUBSTITUTE(SUBSTITUTE(LOWER(TRIM(B16))," ",""),"'",""),"’",""),"·",""),"/",""),"-",""),"(",""),")",""),"（",""),"）",""),"ü","v"),";","|"),"；","|"),",","|"),"，","|"),"、","|")) | G16: =SUBSTITUTE(SUBSTITUTE(SUBSTITUTE(SUBSTITUTE(SUBSTITUTE(SUBSTITUTE(SUBSTITUTE(SUBSTITUTE(SUBSTITUTE(SUBSTITUTE(SUBSTITUTE(SUBSTITUTE(SUBSTITUTE(SUBSTITUTE(SUBSTITUTE(SUBSTITUTE(SUBSTITUTE(SUBSTITUTE(SUBSTITUTE(SUBSTITUTE(SUBSTITUTE(SUBSTITUTE(SUBSTITUTE(SUBSTITUTE(F16,"ā","a"),"á","a"),"ǎ","a"),"à","a"),"ē","e"),"é","e"),"ě","e"),"è","e"),"ī","i"),"í","i"),"ǐ","i"),"ì","i"),"ō","o"),"ó","o"),"ǒ","o"),"ò","o"),"ū","u"),"ú","u"),"ǔ","u"),"ù","u"),"ǖ","v"),"ǘ","v"),"ǚ","v"),"ǜ","v")
A17: =IF(Data_HSK2!E11="","",Data_HSK2!E11) -> văn phòng | C17: =IF(OR(A17="",TRIM(B17)=""),"",IF(OR(ISNUMBER(FIND("|"&F17&"|",Data_HSK2!G11)),AND(F17=G17,ISNUMBER(FIND("|"&G17&"|",Data_HSK2!H11)))),"✅","❌")) | D17: =IF(OR(A17="",$D$5<>"Có"),"",Data_HSK2!B11&" ("&Data_HSK2!C11&")") | F17: =IF(TRIM(B17)="","",SUBSTITUTE(SUBSTITUTE(SUBSTITUTE(SUBSTITUTE(SUBSTITUTE(SUBSTITUTE(SUBSTITUTE(SUBSTITUTE(SUBSTITUTE(SUBSTITUTE(SUBSTITUTE(SUBSTITUTE(SUBSTITUTE(SUBSTITUTE(SUBSTITUTE(SUBSTITUTE(LOWER(TRIM(B17))," ",""),"'",""),"’",""),"·",""),"/",""),"-",""),"(",""),")",""),"（",""),"）",""),"ü","v"),";","|"),"；","|"),",","|"),"，","|"),"、","|")) | G17: =SUBSTITUTE(SUBSTITUTE(SUBSTITUTE(SUBSTITUTE(SUBSTITUTE(SUBSTITUTE(SUBSTITUTE(SUBSTITUTE(SUBSTITUTE(SUBSTITUTE(SUBSTITUTE(SUBSTITUTE(SUBSTITUTE(SUBSTITUTE(SUBSTITUTE(SUBSTITUTE(SUBSTITUTE(SUBSTITUTE(SUBSTITUTE(SUBSTITUTE(SUBSTITUTE(SUBSTITUTE(SUBSTITUTE(SUBSTITUTE(F17,"ā","a"),"á","a"),"ǎ","a"),"à","a"),"ē","e"),"é","e"),"ě","e"),"è","e"),"ī","i"),"í","i"),"ǐ","i"),"ì","i"),"ō","o"),"ó","o"),"ǒ","o"),"ò","o"),"ū","u"),"ú","u"),"ǔ","u"),"ù","u"),"ǖ","v"),"ǘ","v"),"ǚ","v"),"ǜ","v")
A18: =IF(Data_HSK2!E12="","",Data_HSK2!E12) -> nửa đêm | C18: =IF(OR(A18="",TRIM(B18)=""),"",IF(OR(ISNUMBER(FIND("|"&F18&"|",Data_HSK2!G12)),AND(F18=G18,ISNUMBER(FIND("|"&G18&"|",Data_HSK2!H12)))),"✅","❌")) | D18: =IF(OR(A18="",$D$5<>"Có"),"",Data_HSK2!B12&" ("&Data_HSK2!C12&")") | F18: =IF(TRIM(B18)="","",SUBSTITUTE(SUBSTITUTE(SUBSTITUTE(SUBSTITUTE(SUBSTITUTE(SUBSTITUTE(SUBSTITUTE(SUBSTITUTE(SUBSTITUTE(SUBSTITUTE(SUBSTITUTE(SUBSTITUTE(SUBSTITUTE(SUBSTITUTE(SUBSTITUTE(SUBSTITUTE(LOWER(TRIM(B18))," ",""),"'",""),"’",""),"·",""),"/",""),"-",""),"(",""),")",""),"（",""),"）",""),"ü","v"),";","|"),"；","|"),",","|"),"，","|"),"、","|")) | G18: =SUBSTITUTE(SUBSTITUTE(SUBSTITUTE(SUBSTITUTE(SUBSTITUTE(SUBSTITUTE(SUBSTITUTE(SUBSTITUTE(SUBSTITUTE(SUBSTITUTE(SUBSTITUTE(SUBSTITUTE(SUBSTITUTE(SUBSTITUTE(SUBSTITUTE(SUBSTITUTE(SUBSTITUTE(SUBSTITUTE(SUBSTITUTE(SUBSTITUTE(SUBSTITUTE(SUBSTITUTE(SUBSTITUTE(SUBSTITUTE(F18,"ā","a"),"á","a"),"ǎ","a"),"à","a"),"ē","e"),"é","e"),"ě","e"),"è","e"),"ī","i"),"í","i"),"ǐ","i"),"ì","i"),"ō","o"),"ó","o"),"ǒ","o"),"ò","o"),"ū","u"),"ú","u"),"ǔ","u"),"ù","u"),"ǖ","v"),"ǘ","v"),"ǚ","v"),"ǜ","v")
A19: =IF(Data_HSK2!E13="","",Data_HSK2!E13) -> giúp đỡ (帮助) | C19: =IF(OR(A19="",TRIM(B19)=""),"",IF(OR(ISNUMBER(FIND("|"&F19&"|",Data_HSK2!G13)),AND(F19=G19,ISNUMBER(FIND("|"&G19&"|",Data_HSK2!H13)))),"✅","❌")) | D19: =IF(OR(A19="",$D$5<>"Có"),"",Data_HSK2!B13&" ("&Data_HSK2!C13&")") | F19: =IF(TRIM(B19)="","",SUBSTITUTE(SUBSTITUTE(SUBSTITUTE(SUBSTITUTE(SUBSTITUTE(SUBSTITUTE(SUBSTITUTE(SUBSTITUTE(SUBSTITUTE(SUBSTITUTE(SUBSTITUTE(SUBSTITUTE(SUBSTITUTE(SUBSTITUTE(SUBSTITUTE(SUBSTITUTE(LOWER(TRIM(B19))," ",""),"'",""),"’",""),"·",""),"/",""),"-",""),"(",""),")",""),"（",""),"）",""),"ü","v"),";","|"),"；","|"),",","|"),"，","|"),"、","|")) | G19: =SUBSTITUTE(SUBSTITUTE(SUBSTITUTE(SUBSTITUTE(SUBSTITUTE(SUBSTITUTE(SUBSTITUTE(SUBSTITUTE(SUBSTITUTE(SUBSTITUTE(SUBSTITUTE(SUBSTITUTE(SUBSTITUTE(SUBSTITUTE(SUBSTITUTE(SUBSTITUTE(SUBSTITUTE(SUBSTITUTE(SUBSTITUTE(SUBSTITUTE(SUBSTITUTE(SUBSTITUTE(SUBSTITUTE(SUBSTITUTE(F19,"ā","a"),"á","a"),"ǎ","a"),"à","a"),"ē","e"),"é","e"),"ě","e"),"è","e"),"ī","i"),"í","i"),"ǐ","i"),"ì","i"),"ō","o"),"ó","o"),"ǒ","o"),"ò","o"),"ū","u"),"ú","u"),"ǔ","u"),"ù","u"),"ǖ","v"),"ǘ","v"),"ǚ","v"),"ǜ","v")
... A1007: =IF(Data_HSK2!E1001="","",Data_HSK2!E1001) | C1007: =IF(OR(A1007="",TRIM(B1007)=""),"",IF(OR(ISNUMBER(FIND("|"&F1007&"|",Data_HSK2!G1001)),AND(F1007=G1007,ISNUMBER(FIND("|"&G1007&"|",Data_HSK2!H1001)))),"✅","❌")) | D1007: =IF(OR(A1007="",$D$5<>"Có"),"",Data_HSK2!B1001&" ("&Data_HSK2!C1001&")") | F1007: =IF(TRIM(B1007)="","",SUBSTITUTE(SUBSTITUTE(SUBSTITUTE(SUBSTITUTE(SUBSTITUTE(SUBSTITUTE(SUBSTITUTE(SUBSTITUTE(SUBSTITUTE(SUBSTITUTE(SUBSTITUTE(SUBSTITUTE(SUBSTITUTE(SUBSTITUTE(SUBSTITUTE(SUBSTITUTE(LOWER(TRIM(B1007))," ",""),"'",""),"’",""),"·",""),"/",""),"-",""),"(",""),")",""),"（",""),"）",""),"ü","v"),";","|"),"；","|"),",","|"),"，","|"),"、","|")) | G1007: =SUBSTITUTE(SUBSTITUTE(SUBSTITUTE(SUBSTITUTE(SUBSTITUTE(SUBSTITUTE(SUBSTITUTE(SUBSTITUTE(SUBSTITUTE(SUBSTITUTE(SUBSTITUTE(SUBSTITUTE(SUBSTITUTE(SUBSTITUTE(SUBSTITUTE(SUBSTITUTE(SUBSTITUTE(SUBSTITUTE(SUBSTITUTE(SUBSTITUTE(SUBSTITUTE(SUBSTITUTE(SUBSTITUTE(SUBSTITUTE(F1007,"ā","a"),"á","a"),"ǎ","a"),"à","a"),"ē","e"),"é","e"),"ě","e"),"è","e"),"ī","i"),"í","i"),"ǐ","i"),"ì","i"),"ō","o"),"ó","o"),"ǒ","o"),"ò","o"),"ū","u"),"ú","u"),"ǔ","u"),"ù","u"),"ǖ","v"),"ǘ","v"),"ǚ","v"),"ǜ","v")

Sheet Từ vựng HSK3
A1: LUYỆN TẬP TỪ VỰNG HSK 3 (HSK 3.0 — 973 từ)
A2: Nhập chữ Hán giản thể hoặc Pinyin (có/không dấu thanh) vào cột B — chỉ cần sửa các ô màu vàng.
A3: Tổng số câu | B3: Số câu đã làm đúng ✅ | C3: Số câu sai ❌ | D3: Tỷ lệ hoàn thành (%)
A4: =COUNTIF($A$8:$A$1207,"?*") -> 973 | B4: =COUNTIF($C$8:$C$1207,"✅") -> 0 | C4: =COUNTIF($C$8:$C$1207,"❌") -> 0 | D4: =IF(A4=0,0,B4/A4) -> 0
A5: Tiến độ | B5: =REPT("█",ROUND(D4*20,0))&REPT("░",20-ROUND(D4*20,0)) -> ░░░░░░░░░░░░░░░░░░░░ | C5: =IF(B4+C4=0,"Độ chính xác: –","Độ chính xác: "&TEXT(B4/(B4+C4),"0%")) -> Độ chính xác: – | D5: Không
D6: ▲ Hiện gợi ý (Có/Không)
A7: Ý nghĩa | B7: Ô người học nhập | C7: Kết quả | D7: Gợi ý | F7: norm có dấu | G7: norm không dấu
A8: =IF(Data_HSK3!E2="","",Data_HSK3!E2) -> lòng yêu thương | C8: =IF(OR(A8="",TRIM(B8)=""),"",IF(OR(ISNUMBER(FIND("|"&F8&"|",Data_HSK3!G2)),AND(F8=G8,ISNUMBER(FIND("|"&G8&"|",Data_HSK3!H2)))),"✅","❌")) | D8: =IF(OR(A8="",$D$5<>"Có"),"",Data_HSK3!B2&" ("&Data_HSK3!C2&")") | F8: =IF(TRIM(B8)="","",SUBSTITUTE(SUBSTITUTE(SUBSTITUTE(SUBSTITUTE(SUBSTITUTE(SUBSTITUTE(SUBSTITUTE(SUBSTITUTE(SUBSTITUTE(SUBSTITUTE(SUBSTITUTE(SUBSTITUTE(SUBSTITUTE(SUBSTITUTE(SUBSTITUTE(SUBSTITUTE(LOWER(TRIM(B8))," ",""),"'",""),"’",""),"·",""),"/",""),"-",""),"(",""),")",""),"（",""),"）",""),"ü","v"),";","|"),"；","|"),",","|"),"，","|"),"、","|")) | G8: =SUBSTITUTE(SUBSTITUTE(SUBSTITUTE(SUBSTITUTE(SUBSTITUTE(SUBSTITUTE(SUBSTITUTE(SUBSTITUTE(SUBSTITUTE(SUBSTITUTE(SUBSTITUTE(SUBSTITUTE(SUBSTITUTE(SUBSTITUTE(SUBSTITUTE(SUBSTITUTE(SUBSTITUTE(SUBSTITUTE(SUBSTITUTE(SUBSTITUTE(SUBSTITUTE(SUBSTITUTE(SUBSTITUTE(SUBSTITUTE(F8,"ā","a"),"á","a"),"ǎ","a"),"à","a"),"ē","e"),"é","e"),"ě","e"),"è","e"),"ī","i"),"í","i"),"ǐ","i"),"ì","i"),"ō","o"),"ó","o"),"ǒ","o"),"ò","o"),"ū","u"),"ú","u"),"ǔ","u"),"ù","u"),"ǖ","v"),"ǘ","v"),"ǚ","v"),"ǜ","v")
A9: =IF(Data_HSK3!E3="","",Data_HSK3!E3) -> sắp xếp, bố trí | C9: =IF(OR(A9="",TRIM(B9)=""),"",IF(OR(ISNUMBER(FIND("|"&F9&"|",Data_HSK3!G3)),AND(F9=G9,ISNUMBER(FIND("|"&G9&"|",Data_HSK3!H3)))),"✅","❌")) | D9: =IF(OR(A9="",$D$5<>"Có"),"",Data_HSK3!B3&" ("&Data_HSK3!C3&")") | F9: =IF(TRIM(B9)="","",SUBSTITUTE(SUBSTITUTE(SUBSTITUTE(SUBSTITUTE(SUBSTITUTE(SUBSTITUTE(SUBSTITUTE(SUBSTITUTE(SUBSTITUTE(SUBSTITUTE(SUBSTITUTE(SUBSTITUTE(SUBSTITUTE(SUBSTITUTE(SUBSTITUTE(SUBSTITUTE(LOWER(TRIM(B9))," ",""),"'",""),"’",""),"·",""),"/",""),"-",""),"(",""),")",""),"（",""),"）",""),"ü","v"),";","|"),"；","|"),",","|"),"，","|"),"、","|")) | G9: =SUBSTITUTE(SUBSTITUTE(SUBSTITUTE(SUBSTITUTE(SUBSTITUTE(SUBSTITUTE(SUBSTITUTE(SUBSTITUTE(SUBSTITUTE(SUBSTITUTE(SUBSTITUTE(SUBSTITUTE(SUBSTITUTE(SUBSTITUTE(SUBSTITUTE(SUBSTITUTE(SUBSTITUTE(SUBSTITUTE(SUBSTITUTE(SUBSTITUTE(SUBSTITUTE(SUBSTITUTE(SUBSTITUTE(SUBSTITUTE(F9,"ā","a"),"á","a"),"ǎ","a"),"à","a"),"ē","e"),"é","e"),"ě","e"),"è","e"),"ī","i"),"í","i"),"ǐ","i"),"ì","i"),"ō","o"),"ó","o"),"ǒ","o"),"ò","o"),"ū","u"),"ú","u"),"ǔ","u"),"ù","u"),"ǖ","v"),"ǘ","v"),"ǚ","v"),"ǜ","v")
A10: =IF(Data_HSK3!E4="","",Data_HSK3!E4) -> lắp đặt, cài đặt | C10: =IF(OR(A10="",TRIM(B10)=""),"",IF(OR(ISNUMBER(FIND("|"&F10&"|",Data_HSK3!G4)),AND(F10=G10,ISNUMBER(FIND("|"&G10&"|",Data_HSK3!H4)))),"✅","❌")) | D10: =IF(OR(A10="",$D$5<>"Có"),"",Data_HSK3!B4&" ("&Data_HSK3!C4&")") | F10: =IF(TRIM(B10)="","",SUBSTITUTE(SUBSTITUTE(SUBSTITUTE(SUBSTITUTE(SUBSTITUTE(SUBSTITUTE(SUBSTITUTE(SUBSTITUTE(SUBSTITUTE(SUBSTITUTE(SUBSTITUTE(SUBSTITUTE(SUBSTITUTE(SUBSTITUTE(SUBSTITUTE(SUBSTITUTE(LOWER(TRIM(B10))," ",""),"'",""),"’",""),"·",""),"/",""),"-",""),"(",""),")",""),"（",""),"）",""),"ü","v"),";","|"),"；","|"),",","|"),"，","|"),"、","|")) | G10: =SUBSTITUTE(SUBSTITUTE(SUBSTITUTE(SUBSTITUTE(SUBSTITUTE(SUBSTITUTE(SUBSTITUTE(SUBSTITUTE(SUBSTITUTE(SUBSTITUTE(SUBSTITUTE(SUBSTITUTE(SUBSTITUTE(SUBSTITUTE(SUBSTITUTE(SUBSTITUTE(SUBSTITUTE(SUBSTITUTE(SUBSTITUTE(SUBSTITUTE(SUBSTITUTE(SUBSTITUTE(SUBSTITUTE(SUBSTITUTE(F10,"ā","a"),"á","a"),"ǎ","a"),"à","a"),"ē","e"),"é","e"),"ě","e"),"è","e"),"ī","i"),"í","i"),"ǐ","i"),"ì","i"),"ō","o"),"ó","o"),"ǒ","o"),"ò","o"),"ū","u"),"ú","u"),"ǔ","u"),"ù","u"),"ǖ","v"),"ǘ","v"),"ǚ","v"),"ǜ","v")
A11: =IF(Data_HSK3!E5="","",Data_HSK3!E5) -> ấn, bấm; theo (1 chữ) | C11: =IF(OR(A11="",TRIM(B11)=""),"",IF(OR(ISNUMBER(FIND("|"&F11&"|",Data_HSK3!G5)),AND(F11=G11,ISNUMBER(FIND("|"&G11&"|",Data_HSK3!H5)))),"✅","❌")) | D11: =IF(OR(A11="",$D$5<>"Có"),"",Data_HSK3!B5&" ("&Data_HSK3!C5&")") | F11: =IF(TRIM(B11)="","",SUBSTITUTE(SUBSTITUTE(SUBSTITUTE(SUBSTITUTE(SUBSTITUTE(SUBSTITUTE(SUBSTITUTE(SUBSTITUTE(SUBSTITUTE(SUBSTITUTE(SUBSTITUTE(SUBSTITUTE(SUBSTITUTE(SUBSTITUTE(SUBSTITUTE(SUBSTITUTE(LOWER(TRIM(B11))," ",""),"'",""),"’",""),"·",""),"/",""),"-",""),"(",""),")",""),"（",""),"）",""),"ü","v"),";","|"),"；","|"),",","|"),"，","|"),"、","|")) | G11: =SUBSTITUTE(SUBSTITUTE(SUBSTITUTE(SUBSTITUTE(SUBSTITUTE(SUBSTITUTE(SUBSTITUTE(SUBSTITUTE(SUBSTITUTE(SUBSTITUTE(SUBSTITUTE(SUBSTITUTE(SUBSTITUTE(SUBSTITUTE(SUBSTITUTE(SUBSTITUTE(SUBSTITUTE(SUBSTITUTE(SUBSTITUTE(SUBSTITUTE(SUBSTITUTE(SUBSTITUTE(SUBSTITUTE(SUBSTITUTE(F11,"ā","a"),"á","a"),"ǎ","a"),"à","a"),"ē","e"),"é","e"),"ě","e"),"è","e"),"ī","i"),"í","i"),"ǐ","i"),"ì","i"),"ō","o"),"ó","o"),"ǒ","o"),"ò","o"),"ū","u"),"ú","u"),"ǔ","u"),"ù","u"),"ǖ","v"),"ǘ","v"),"ǚ","v"),"ǜ","v")
A12: =IF(Data_HSK3!E6="","",Data_HSK3!E6) -> theo, căn cứ theo | C12: =IF(OR(A12="",TRIM(B12)=""),"",IF(OR(ISNUMBER(FIND("|"&F12&"|",Data_HSK3!G6)),AND(F12=G12,ISNUMBER(FIND("|"&G12&"|",Data_HSK3!H6)))),"✅","❌")) | D12: =IF(OR(A12="",$D$5<>"Có"),"",Data_HSK3!B6&" ("&Data_HSK3!C6&")") | F12: =IF(TRIM(B12)="","",SUBSTITUTE(SUBSTITUTE(SUBSTITUTE(SUBSTITUTE(SUBSTITUTE(SUBSTITUTE(SUBSTITUTE(SUBSTITUTE(SUBSTITUTE(SUBSTITUTE(SUBSTITUTE(SUBSTITUTE(SUBSTITUTE(SUBSTITUTE(SUBSTITUTE(SUBSTITUTE(LOWER(TRIM(B12))," ",""),"'",""),"’",""),"·",""),"/",""),"-",""),"(",""),")",""),"（",""),"）",""),"ü","v"),";","|"),"；","|"),",","|"),"，","|"),"、","|")) | G12: =SUBSTITUTE(SUBSTITUTE(SUBSTITUTE(SUBSTITUTE(SUBSTITUTE(SUBSTITUTE(SUBSTITUTE(SUBSTITUTE(SUBSTITUTE(SUBSTITUTE(SUBSTITUTE(SUBSTITUTE(SUBSTITUTE(SUBSTITUTE(SUBSTITUTE(SUBSTITUTE(SUBSTITUTE(SUBSTITUTE(SUBSTITUTE(SUBSTITUTE(SUBSTITUTE(SUBSTITUTE(SUBSTITUTE(SUBSTITUTE(F12,"ā","a"),"á","a"),"ǎ","a"),"à","a"),"ē","e"),"é","e"),"ě","e"),"è","e"),"ī","i"),"í","i"),"ǐ","i"),"ì","i"),"ō","o"),"ó","o"),"ǒ","o"),"ò","o"),"ū","u"),"ú","u"),"ǔ","u"),"ù","u"),"ǖ","v"),"ǘ","v"),"ǚ","v"),"ǜ","v")
A13: =IF(Data_HSK3!E7="","",Data_HSK3!E7) -> đem, lấy (giới từ câu chữ 把) | C13: =IF(OR(A13="",TRIM(B13)=""),"",IF(OR(ISNUMBER(FIND("|"&F13&"|",Data_HSK3!G7)),AND(F13=G13,ISNUMBER(FIND("|"&G13&"|",Data_HSK3!H7)))),"✅","❌")) | D13: =IF(OR(A13="",$D$5<>"Có"),"",Data_HSK3!B7&" ("&Data_HSK3!C7&")") | F13: =IF(TRIM(B13)="","",SUBSTITUTE(SUBSTITUTE(SUBSTITUTE(SUBSTITUTE(SUBSTITUTE(SUBSTITUTE(SUBSTITUTE(SUBSTITUTE(SUBSTITUTE(SUBSTITUTE(SUBSTITUTE(SUBSTITUTE(SUBSTITUTE(SUBSTITUTE(SUBSTITUTE(SUBSTITUTE(LOWER(TRIM(B13))," ",""),"'",""),"’",""),"·",""),"/",""),"-",""),"(",""),")",""),"（",""),"）",""),"ü","v"),";","|"),"；","|"),",","|"),"，","|"),"、","|")) | G13: =SUBSTITUTE(SUBSTITUTE(SUBSTITUTE(SUBSTITUTE(SUBSTITUTE(SUBSTITUTE(SUBSTITUTE(SUBSTITUTE(SUBSTITUTE(SUBSTITUTE(SUBSTITUTE(SUBSTITUTE(SUBSTITUTE(SUBSTITUTE(SUBSTITUTE(SUBSTITUTE(SUBSTITUTE(SUBSTITUTE(SUBSTITUTE(SUBSTITUTE(SUBSTITUTE(SUBSTITUTE(SUBSTITUTE(SUBSTITUTE(F13,"ā","a"),"á","a"),"ǎ","a"),"à","a"),"ē","e"),"é","e"),"ě","e"),"è","e"),"ī","i"),"í","i"),"ǐ","i"),"ì","i"),"ō","o"),"ó","o"),"ǒ","o"),"ò","o"),"ū","u"),"ú","u"),"ǔ","u"),"ù","u"),"ǖ","v"),"ǘ","v"),"ǚ","v"),"ǜ","v")
A14: =IF(Data_HSK3!E8="","",Data_HSK3!E8) -> cái, chiếc (vật có tay cầm); nắm | C14: =IF(OR(A14="",TRIM(B14)=""),"",IF(OR(ISNUMBER(FIND("|"&F14&"|",Data_HSK3!G8)),AND(F14=G14,ISNUMBER(FIND("|"&G14&"|",Data_HSK3!H8)))),"✅","❌")) | D14: =IF(OR(A14="",$D$5<>"Có"),"",Data_HSK3!B8&" ("&Data_HSK3!C8&")") | F14: =IF(TRIM(B14)="","",SUBSTITUTE(SUBSTITUTE(SUBSTITUTE(SUBSTITUTE(SUBSTITUTE(SUBSTITUTE(SUBSTITUTE(SUBSTITUTE(SUBSTITUTE(SUBSTITUTE(SUBSTITUTE(SUBSTITUTE(SUBSTITUTE(SUBSTITUTE(SUBSTITUTE(SUBSTITUTE(LOWER(TRIM(B14))," ",""),"'",""),"’",""),"·",""),"/",""),"-",""),"(",""),")",""),"（",""),"）",""),"ü","v"),";","|"),"；","|"),",","|"),"，","|"),"、","|")) | G14: =SUBSTITUTE(SUBSTITUTE(SUBSTITUTE(SUBSTITUTE(SUBSTITUTE(SUBSTITUTE(SUBSTITUTE(SUBSTITUTE(SUBSTITUTE(SUBSTITUTE(SUBSTITUTE(SUBSTITUTE(SUBSTITUTE(SUBSTITUTE(SUBSTITUTE(SUBSTITUTE(SUBSTITUTE(SUBSTITUTE(SUBSTITUTE(SUBSTITUTE(SUBSTITUTE(SUBSTITUTE(SUBSTITUTE(SUBSTITUTE(F14,"ā","a"),"á","a"),"ǎ","a"),"à","a"),"ē","e"),"é","e"),"ě","e"),"è","e"),"ī","i"),"í","i"),"ǐ","i"),"ì","i"),"ō","o"),"ó","o"),"ǒ","o"),"ò","o"),"ū","u"),"ú","u"),"ǔ","u"),"ù","u"),"ǖ","v"),"ǘ","v"),"ǚ","v"),"ǜ","v")
A15: =IF(Data_HSK3!E9="","",Data_HSK3!E9) -> nắm chắc; sự chắc chắn | C15: =IF(OR(A15="",TRIM(B15)=""),"",IF(OR(ISNUMBER(FIND("|"&F15&"|",Data_HSK3!G9)),AND(F15=G15,ISNUMBER(FIND("|"&G15&"|",Data_HSK3!H9)))),"✅","❌")) | D15: =IF(OR(A15="",$D$5<>"Có"),"",Data_HSK3!B9&" ("&Data_HSK3!C9&")") | F15: =IF(TRIM(B15)="","",SUBSTITUTE(SUBSTITUTE(SUBSTITUTE(SUBSTITUTE(SUBSTITUTE(SUBSTITUTE(SUBSTITUTE(SUBSTITUTE(SUBSTITUTE(SUBSTITUTE(SUBSTITUTE(SUBSTITUTE(SUBSTITUTE(SUBSTITUTE(SUBSTITUTE(SUBSTITUTE(LOWER(TRIM(B15))," ",""),"'",""),"’",""),"·",""),"/",""),"-",""),"(",""),")",""),"（",""),"）",""),"ü","v"),";","|"),"；","|"),",","|"),"，","|"),"、","|")) | G15: =SUBSTITUTE(SUBSTITUTE(SUBSTITUTE(SUBSTITUTE(SUBSTITUTE(SUBSTITUTE(SUBSTITUTE(SUBSTITUTE(SUBSTITUTE(SUBSTITUTE(SUBSTITUTE(SUBSTITUTE(SUBSTITUTE(SUBSTITUTE(SUBSTITUTE(SUBSTITUTE(SUBSTITUTE(SUBSTITUTE(SUBSTITUTE(SUBSTITUTE(SUBSTITUTE(SUBSTITUTE(SUBSTITUTE(SUBSTITUTE(F15,"ā","a"),"á","a"),"ǎ","a"),"à","a"),"ē","e"),"é","e"),"ě","e"),"è","e"),"ī","i"),"í","i"),"ǐ","i"),"ì","i"),"ō","o"),"ó","o"),"ǒ","o"),"ò","o"),"ū","u"),"ú","u"),"ǔ","u"),"ù","u"),"ǖ","v"),"ǘ","v"),"ǚ","v"),"ǜ","v")
A16: =IF(Data_HSK3!E10="","",Data_HSK3!E10) -> uổng công, vô ích (phó từ) | C16: =IF(OR(A16="",TRIM(B16)=""),"",IF(OR(ISNUMBER(FIND("|"&F16&"|",Data_HSK3!G10)),AND(F16=G16,ISNUMBER(FIND("|"&G16&"|",Data_HSK3!H10)))),"✅","❌")) | D16: =IF(OR(A16="",$D$5<>"Có"),"",Data_HSK3!B10&" ("&Data_HSK3!C10&")") | F16: =IF(TRIM(B16)="","",SUBSTITUTE(SUBSTITUTE(SUBSTITUTE(SUBSTITUTE(SUBSTITUTE(SUBSTITUTE(SUBSTITUTE(SUBSTITUTE(SUBSTITUTE(SUBSTITUTE(SUBSTITUTE(SUBSTITUTE(SUBSTITUTE(SUBSTITUTE(SUBSTITUTE(SUBSTITUTE(LOWER(TRIM(B16))," ",""),"'",""),"’",""),"·",""),"/",""),"-",""),"(",""),")",""),"（",""),"）",""),"ü","v"),";","|"),"；","|"),",","|"),"，","|"),"、","|")) | G16: =SUBSTITUTE(SUBSTITUTE(SUBSTITUTE(SUBSTITUTE(SUBSTITUTE(SUBSTITUTE(SUBSTITUTE(SUBSTITUTE(SUBSTITUTE(SUBSTITUTE(SUBSTITUTE(SUBSTITUTE(SUBSTITUTE(SUBSTITUTE(SUBSTITUTE(SUBSTITUTE(SUBSTITUTE(SUBSTITUTE(SUBSTITUTE(SUBSTITUTE(SUBSTITUTE(SUBSTITUTE(SUBSTITUTE(SUBSTITUTE(F16,"ā","a"),"á","a"),"ǎ","a"),"à","a"),"ē","e"),"é","e"),"ě","e"),"è","e"),"ī","i"),"í","i"),"ǐ","i"),"ì","i"),"ō","o"),"ó","o"),"ǒ","o"),"ò","o"),"ū","u"),"ú","u"),"ǔ","u"),"ù","u"),"ǖ","v"),"ǘ","v"),"ǚ","v"),"ǜ","v")
A17: =IF(Data_HSK3!E11="","",Data_HSK3!E11) -> cải thảo | C17: =IF(OR(A17="",TRIM(B17)=""),"",IF(OR(ISNUMBER(FIND("|"&F17&"|",Data_HSK3!G11)),AND(F17=G17,ISNUMBER(FIND("|"&G17&"|",Data_HSK3!H11)))),"✅","❌")) | D17: =IF(OR(A17="",$D$5<>"Có"),"",Data_HSK3!B11&" ("&Data_HSK3!C11&")") | F17: =IF(TRIM(B17)="","",SUBSTITUTE(SUBSTITUTE(SUBSTITUTE(SUBSTITUTE(SUBSTITUTE(SUBSTITUTE(SUBSTITUTE(SUBSTITUTE(SUBSTITUTE(SUBSTITUTE(SUBSTITUTE(SUBSTITUTE(SUBSTITUTE(SUBSTITUTE(SUBSTITUTE(SUBSTITUTE(LOWER(TRIM(B17))," ",""),"'",""),"’",""),"·",""),"/",""),"-",""),"(",""),")",""),"（",""),"）",""),"ü","v"),";","|"),"；","|"),",","|"),"，","|"),"、","|")) | G17: =SUBSTITUTE(SUBSTITUTE(SUBSTITUTE(SUBSTITUTE(SUBSTITUTE(SUBSTITUTE(SUBSTITUTE(SUBSTITUTE(SUBSTITUTE(SUBSTITUTE(SUBSTITUTE(SUBSTITUTE(SUBSTITUTE(SUBSTITUTE(SUBSTITUTE(SUBSTITUTE(SUBSTITUTE(SUBSTITUTE(SUBSTITUTE(SUBSTITUTE(SUBSTITUTE(SUBSTITUTE(SUBSTITUTE(SUBSTITUTE(F17,"ā","a"),"á","a"),"ǎ","a"),"à","a"),"ē","e"),"é","e"),"ě","e"),"è","e"),"ī","i"),"í","i"),"ǐ","i"),"ì","i"),"ō","o"),"ó","o"),"ǒ","o"),"ò","o"),"ū","u"),"ú","u"),"ǔ","u"),"ù","u"),"ǖ","v"),"ǘ","v"),"ǚ","v"),"ǜ","v")
A18: =IF(Data_HSK3!E12="","",Data_HSK3!E12) -> lớp học, khối lớp (班级) | C18: =IF(OR(A18="",TRIM(B18)=""),"",IF(OR(ISNUMBER(FIND("|"&F18&"|",Data_HSK3!G12)),AND(F18=G18,ISNUMBER(FIND("|"&G18&"|",Data_HSK3!H12)))),"✅","❌")) | D18: =IF(OR(A18="",$D$5<>"Có"),"",Data_HSK3!B12&" ("&Data_HSK3!C12&")") | F18: =IF(TRIM(B18)="","",SUBSTITUTE(SUBSTITUTE(SUBSTITUTE(SUBSTITUTE(SUBSTITUTE(SUBSTITUTE(SUBSTITUTE(SUBSTITUTE(SUBSTITUTE(SUBSTITUTE(SUBSTITUTE(SUBSTITUTE(SUBSTITUTE(SUBSTITUTE(SUBSTITUTE(SUBSTITUTE(LOWER(TRIM(B18))," ",""),"'",""),"’",""),"·",""),"/",""),"-",""),"(",""),")",""),"（",""),"）",""),"ü","v"),";","|"),"；","|"),",","|"),"，","|"),"、","|")) | G18: =SUBSTITUTE(SUBSTITUTE(SUBSTITUTE(SUBSTITUTE(SUBSTITUTE(SUBSTITUTE(SUBSTITUTE(SUBSTITUTE(SUBSTITUTE(SUBSTITUTE(SUBSTITUTE(SUBSTITUTE(SUBSTITUTE(SUBSTITUTE(SUBSTITUTE(SUBSTITUTE(SUBSTITUTE(SUBSTITUTE(SUBSTITUTE(SUBSTITUTE(SUBSTITUTE(SUBSTITUTE(SUBSTITUTE(SUBSTITUTE(F18,"ā","a"),"á","a"),"ǎ","a"),"à","a"),"ē","e"),"é","e"),"ě","e"),"è","e"),"ī","i"),"í","i"),"ǐ","i"),"ì","i"),"ō","o"),"ó","o"),"ǒ","o"),"ò","o"),"ū","u"),"ú","u"),"ǔ","u"),"ù","u"),"ǖ","v"),"ǘ","v"),"ǚ","v"),"ǜ","v")
A19: =IF(Data_HSK3!E13="","",Data_HSK3!E13) -> chuyển, khuân, dọn | C19: =IF(OR(A19="",TRIM(B19)=""),"",IF(OR(ISNUMBER(FIND("|"&F19&"|",Data_HSK3!G13)),AND(F19=G19,ISNUMBER(FIND("|"&G19&"|",Data_HSK3!H13)))),"✅","❌")) | D19: =IF(OR(A19="",$D$5<>"Có"),"",Data_HSK3!B13&" ("&Data_HSK3!C13&")") | F19: =IF(TRIM(B19)="","",SUBSTITUTE(SUBSTITUTE(SUBSTITUTE(SUBSTITUTE(SUBSTITUTE(SUBSTITUTE(SUBSTITUTE(SUBSTITUTE(SUBSTITUTE(SUBSTITUTE(SUBSTITUTE(SUBSTITUTE(SUBSTITUTE(SUBSTITUTE(SUBSTITUTE(SUBSTITUTE(LOWER(TRIM(B19))," ",""),"'",""),"’",""),"·",""),"/",""),"-",""),"(",""),")",""),"（",""),"）",""),"ü","v"),";","|"),"；","|"),",","|"),"，","|"),"、","|")) | G19: =SUBSTITUTE(SUBSTITUTE(SUBSTITUTE(SUBSTITUTE(SUBSTITUTE(SUBSTITUTE(SUBSTITUTE(SUBSTITUTE(SUBSTITUTE(SUBSTITUTE(SUBSTITUTE(SUBSTITUTE(SUBSTITUTE(SUBSTITUTE(SUBSTITUTE(SUBSTITUTE(SUBSTITUTE(SUBSTITUTE(SUBSTITUTE(SUBSTITUTE(SUBSTITUTE(SUBSTITUTE(SUBSTITUTE(SUBSTITUTE(F19,"ā","a"),"á","a"),"ǎ","a"),"à","a"),"ē","e"),"é","e"),"ě","e"),"è","e"),"ī","i"),"í","i"),"ǐ","i"),"ì","i"),"ō","o"),"ó","o"),"ǒ","o"),"ò","o"),"ū","u"),"ú","u"),"ǔ","u"),"ù","u"),"ǖ","v"),"ǘ","v"),"ǚ","v"),"ǜ","v")
... A1207: =IF(Data_HSK3!E1201="","",Data_HSK3!E1201) | C1207: =IF(OR(A1207="",TRIM(B1207)=""),"",IF(OR(ISNUMBER(FIND("|"&F1207&"|",Data_HSK3!G1201)),AND(F1207=G1207,ISNUMBER(FIND("|"&G1207&"|",Data_HSK3!H1201)))),"✅","❌")) | D1207: =IF(OR(A1207="",$D$5<>"Có"),"",Data_HSK3!B1201&" ("&Data_HSK3!C1201&")") | F1207: =IF(TRIM(B1207)="","",SUBSTITUTE(SUBSTITUTE(SUBSTITUTE(SUBSTITUTE(SUBSTITUTE(SUBSTITUTE(SUBSTITUTE(SUBSTITUTE(SUBSTITUTE(SUBSTITUTE(SUBSTITUTE(SUBSTITUTE(SUBSTITUTE(SUBSTITUTE(SUBSTITUTE(SUBSTITUTE(LOWER(TRIM(B1207))," ",""),"'",""),"’",""),"·",""),"/",""),"-",""),"(",""),")",""),"（",""),"）",""),"ü","v"),";","|"),"；","|"),",","|"),"，","|"),"、","|")) | G1207: =SUBSTITUTE(SUBSTITUTE(SUBSTITUTE(SUBSTITUTE(SUBSTITUTE(SUBSTITUTE(SUBSTITUTE(SUBSTITUTE(SUBSTITUTE(SUBSTITUTE(SUBSTITUTE(SUBSTITUTE(SUBSTITUTE(SUBSTITUTE(SUBSTITUTE(SUBSTITUTE(SUBSTITUTE(SUBSTITUTE(SUBSTITUTE(SUBSTITUTE(SUBSTITUTE(SUBSTITUTE(SUBSTITUTE(SUBSTITUTE(F1207,"ā","a"),"á","a"),"ǎ","a"),"à","a"),"ē","e"),"é","e"),"ě","e"),"è","e"),"ī","i"),"í","i"),"ǐ","i"),"ì","i"),"ō","o"),"ó","o"),"ǒ","o"),"ò","o"),"ū","u"),"ú","u"),"ǔ","u"),"ù","u"),"ǖ","v"),"ǘ","v"),"ǚ","v"),"ǜ","v")

Sheet Từ vựng HSK4
A1: LUYỆN TẬP TỪ VỰNG HSK 4 (HSK 3.0 — 1000 từ)
A2: Nhập chữ Hán giản thể hoặc Pinyin (có/không dấu thanh) vào cột B — chỉ cần sửa các ô màu vàng.
A3: Tổng số câu | B3: Số câu đã làm đúng ✅ | C3: Số câu sai ❌ | D3: Tỷ lệ hoàn thành (%)
A4: =COUNTIF($A$8:$A$1207,"?*") -> 1000 | B4: =COUNTIF($C$8:$C$1207,"✅") -> 0 | C4: =COUNTIF($C$8:$C$1207,"❌") -> 0 | D4: =IF(A4=0,0,B4/A4) -> 0
A5: Tiến độ | B5: =REPT("█",ROUND(D4*20,0))&REPT("░",20-ROUND(D4*20,0)) -> ░░░░░░░░░░░░░░░░░░░░ | C5: =IF(B4+C4=0,"Độ chính xác: –","Độ chính xác: "&TEXT(B4/(B4+C4),"0%")) -> Độ chính xác: – | D5: Không
D6: ▲ Hiện gợi ý (Có/Không)
A7: Ý nghĩa | B7: Ô người học nhập | C7: Kết quả | D7: Gợi ý | F7: norm có dấu | G7: norm không dấu
A8: =IF(Data_HSK4!E2="","",Data_HSK4!E2) -> cô, dì, thím | C8: =IF(OR(A8="",TRIM(B8)=""),"",IF(OR(ISNUMBER(FIND("|"&F8&"|",Data_HSK4!G2)),AND(F8=G8,ISNUMBER(FIND("|"&G8&"|",Data_HSK4!H2)))),"✅","❌")) | D8: =IF(OR(A8="",$D$5<>"Có"),"",Data_HSK4!B2&" ("&Data_HSK4!C2&")") | F8: =IF(TRIM(B8)="","",SUBSTITUTE(SUBSTITUTE(SUBSTITUTE(SUBSTITUTE(SUBSTITUTE(SUBSTITUTE(SUBSTITUTE(SUBSTITUTE(SUBSTITUTE(SUBSTITUTE(SUBSTITUTE(SUBSTITUTE(SUBSTITUTE(SUBSTITUTE(SUBSTITUTE(SUBSTITUTE(LOWER(TRIM(B8))," ",""),"'",""),"’",""),"·",""),"/",""),"-",""),"(",""),")",""),"（",""),"）",""),"ü","v"),";","|"),"；","|"),",","|"),"，","|"),"、","|")) | G8: =SUBSTITUTE(SUBSTITUTE(SUBSTITUTE(SUBSTITUTE(SUBSTITUTE(SUBSTITUTE(SUBSTITUTE(SUBSTITUTE(SUBSTITUTE(SUBSTITUTE(SUBSTITUTE(SUBSTITUTE(SUBSTITUTE(SUBSTITUTE(SUBSTITUTE(SUBSTITUTE(SUBSTITUTE(SUBSTITUTE(SUBSTITUTE(SUBSTITUTE(SUBSTITUTE(SUBSTITUTE(SUBSTITUTE(SUBSTITUTE(F8,"ā","a"),"á","a"),"ǎ","a"),"à","a"),"ē","e"),"é","e"),"ě","e"),"è","e"),"ī","i"),"í","i"),"ǐ","i"),"ì","i"),"ō","o"),"ó","o"),"ǒ","o"),"ò","o"),"ū","u"),"ú","u"),"ǔ","u"),"ù","u"),"ǖ","v"),"ǘ","v"),"ǚ","v"),"ǜ","v")
A9: =IF(Data_HSK4!E3="","",Data_HSK4!E3) -> a, à (thán từ) | C9: =IF(OR(A9="",TRIM(B9)=""),"",IF(OR(ISNUMBER(FIND("|"&F9&"|",Data_HSK4!G3)),AND(F9=G9,ISNUMBER(FIND("|"&G9&"|",Data_HSK4!H3)))),"✅","❌")) | D9: =IF(OR(A9="",$D$5<>"Có"),"",Data_HSK4!B3&" ("&Data_HSK4!C3&")") | F9: =IF(TRIM(B9)="","",SUBSTITUTE(SUBSTITUTE(SUBSTITUTE(SUBSTITUTE(SUBSTITUTE(SUBSTITUTE(SUBSTITUTE(SUBSTITUTE(SUBSTITUTE(SUBSTITUTE(SUBSTITUTE(SUBSTITUTE(SUBSTITUTE(SUBSTITUTE(SUBSTITUTE(SUBSTITUTE(LOWER(TRIM(B9))," ",""),"'",""),"’",""),"·",""),"/",""),"-",""),"(",""),")",""),"（",""),"）",""),"ü","v"),";","|"),"；","|"),",","|"),"，","|"),"、","|")) | G9: =SUBSTITUTE(SUBSTITUTE(SUBSTITUTE(SUBSTITUTE(SUBSTITUTE(SUBSTITUTE(SUBSTITUTE(SUBSTITUTE(SUBSTITUTE(SUBSTITUTE(SUBSTITUTE(SUBSTITUTE(SUBSTITUTE(SUBSTITUTE(SUBSTITUTE(SUBSTITUTE(SUBSTITUTE(SUBSTITUTE(SUBSTITUTE(SUBSTITUTE(SUBSTITUTE(SUBSTITUTE(SUBSTITUTE(SUBSTITUTE(F9,"ā","a"),"á","a"),"ǎ","a"),"à","a"),"ē","e"),"é","e"),"ě","e"),"è","e"),"ī","i"),"í","i"),"ǐ","i"),"ì","i"),"ō","o"),"ó","o"),"ǒ","o"),"ò","o"),"ū","u"),"ú","u"),"ǔ","u"),"ù","u"),"ǖ","v"),"ǘ","v"),"ǚ","v"),"ǜ","v")
A10: =IF(Data_HSK4!E4="","",Data_HSK4!E4) -> thấp | C10: =IF(OR(A10="",TRIM(B10)=""),"",IF(OR(ISNUMBER(FIND("|"&F10&"|",Data_HSK4!G4)),AND(F10=G10,ISNUMBER(FIND("|"&G10&"|",Data_HSK4!H4)))),"✅","❌")) | D10: =IF(OR(A10="",$D$5<>"Có"),"",Data_HSK4!B4&" ("&Data_HSK4!C4&")") | F10: =IF(TRIM(B10)="","",SUBSTITUTE(SUBSTITUTE(SUBSTITUTE(SUBSTITUTE(SUBSTITUTE(SUBSTITUTE(SUBSTITUTE(SUBSTITUTE(SUBSTITUTE(SUBSTITUTE(SUBSTITUTE(SUBSTITUTE(SUBSTITUTE(SUBSTITUTE(SUBSTITUTE(SUBSTITUTE(LOWER(TRIM(B10))," ",""),"'",""),"’",""),"·",""),"/",""),"-",""),"(",""),")",""),"（",""),"）",""),"ü","v"),";","|"),"；","|"),",","|"),"，","|"),"、","|")) | G10: =SUBSTITUTE(SUBSTITUTE(SUBSTITUTE(SUBSTITUTE(SUBSTITUTE(SUBSTITUTE(SUBSTITUTE(SUBSTITUTE(SUBSTITUTE(SUBSTITUTE(SUBSTITUTE(SUBSTITUTE(SUBSTITUTE(SUBSTITUTE(SUBSTITUTE(SUBSTITUTE(SUBSTITUTE(SUBSTITUTE(SUBSTITUTE(SUBSTITUTE(SUBSTITUTE(SUBSTITUTE(SUBSTITUTE(SUBSTITUTE(F10,"ā","a"),"á","a"),"ǎ","a"),"à","a"),"ē","e"),"é","e"),"ě","e"),"è","e"),"ī","i"),"í","i"),"ǐ","i"),"ì","i"),"ō","o"),"ó","o"),"ǒ","o"),"ò","o"),"ū","u"),"ú","u"),"ǔ","u"),"ù","u"),"ǖ","v"),"ǘ","v"),"ǚ","v"),"ǜ","v")
A11: =IF(Data_HSK4!E5="","",Data_HSK4!E5) -> thấp bé | C11: =IF(OR(A11="",TRIM(B11)=""),"",IF(OR(ISNUMBER(FIND("|"&F11&"|",Data_HSK4!G5)),AND(F11=G11,ISNUMBER(FIND("|"&G11&"|",Data_HSK4!H5)))),"✅","❌")) | D11: =IF(OR(A11="",$D$5<>"Có"),"",Data_HSK4!B5&" ("&Data_HSK4!C5&")") | F11: =IF(TRIM(B11)="","",SUBSTITUTE(SUBSTITUTE(SUBSTITUTE(SUBSTITUTE(SUBSTITUTE(SUBSTITUTE(SUBSTITUTE(SUBSTITUTE(SUBSTITUTE(SUBSTITUTE(SUBSTITUTE(SUBSTITUTE(SUBSTITUTE(SUBSTITUTE(SUBSTITUTE(SUBSTITUTE(LOWER(TRIM(B11))," ",""),"'",""),"’",""),"·",""),"/",""),"-",""),"(",""),")",""),"（",""),"）",""),"ü","v"),";","|"),"；","|"),",","|"),"，","|"),"、","|")) | G11: =SUBSTITUTE(SUBSTITUTE(SUBSTITUTE(SUBSTITUTE(SUBSTITUTE(SUBSTITUTE(SUBSTITUTE(SUBSTITUTE(SUBSTITUTE(SUBSTITUTE(SUBSTITUTE(SUBSTITUTE(SUBSTITUTE(SUBSTITUTE(SUBSTITUTE(SUBSTITUTE(SUBSTITUTE(SUBSTITUTE(SUBSTITUTE(SUBSTITUTE(SUBSTITUTE(SUBSTITUTE(SUBSTITUTE(SUBSTITUTE(F11,"ā","a"),"á","a"),"ǎ","a"),"à","a"),"ē","e"),"é","e"),"ě","e"),"è","e"),"ī","i"),"í","i"),"ǐ","i"),"ì","i"),"ō","o"),"ó","o"),"ǒ","o"),"ò","o"),"ū","u"),"ú","u"),"ǔ","u"),"ù","u"),"ǖ","v"),"ǘ","v"),"ǚ","v"),"ǜ","v")
A12: =IF(Data_HSK4!E6="","",Data_HSK4!E6) -> yêu nước | C12: =IF(OR(A12="",TRIM(B12)=""),"",IF(OR(ISNUMBER(FIND("|"&F12&"|",Data_HSK4!G6)),AND(F12=G12,ISNUMBER(FIND("|"&G12&"|",Data_HSK4!H6)))),"✅","❌")) | D12: =IF(OR(A12="",$D$5<>"Có"),"",Data_HSK4!B6&" ("&Data_HSK4!C6&")") | F12: =IF(TRIM(B12)="","",SUBSTITUTE(SUBSTITUTE(SUBSTITUTE(SUBSTITUTE(SUBSTITUTE(SUBSTITUTE(SUBSTITUTE(SUBSTITUTE(SUBSTITUTE(SUBSTITUTE(SUBSTITUTE(SUBSTITUTE(SUBSTITUTE(SUBSTITUTE(SUBSTITUTE(SUBSTITUTE(LOWER(TRIM(B12))," ",""),"'",""),"’",""),"·",""),"/",""),"-",""),"(",""),")",""),"（",""),"）",""),"ü","v"),";","|"),"；","|"),",","|"),"，","|"),"、","|")) | G12: =SUBSTITUTE(SUBSTITUTE(SUBSTITUTE(SUBSTITUTE(SUBSTITUTE(SUBSTITUTE(SUBSTITUTE(SUBSTITUTE(SUBSTITUTE(SUBSTITUTE(SUBSTITUTE(SUBSTITUTE(SUBSTITUTE(SUBSTITUTE(SUBSTITUTE(SUBSTITUTE(SUBSTITUTE(SUBSTITUTE(SUBSTITUTE(SUBSTITUTE(SUBSTITUTE(SUBSTITUTE(SUBSTITUTE(SUBSTITUTE(F12,"ā","a"),"á","a"),"ǎ","a"),"à","a"),"ē","e"),"é","e"),"ě","e"),"è","e"),"ī","i"),"í","i"),"ǐ","i"),"ì","i"),"ō","o"),"ó","o"),"ǒ","o"),"ò","o"),"ū","u"),"ú","u"),"ǔ","u"),"ù","u"),"ǖ","v"),"ǘ","v"),"ǚ","v"),"ǜ","v")
A13: =IF(Data_HSK4!E7="","",Data_HSK4!E7) -> yêu quý, chăm sóc | C13: =IF(OR(A13="",TRIM(B13)=""),"",IF(OR(ISNUMBER(FIND("|"&F13&"|",Data_HSK4!G7)),AND(F13=G13,ISNUMBER(FIND("|"&G13&"|",Data_HSK4!H7)))),"✅","❌")) | D13: =IF(OR(A13="",$D$5<>"Có"),"",Data_HSK4!B7&" ("&Data_HSK4!C7&")") | F13: =IF(TRIM(B13)="","",SUBSTITUTE(SUBSTITUTE(SUBSTITUTE(SUBSTITUTE(SUBSTITUTE(SUBSTITUTE(SUBSTITUTE(SUBSTITUTE(SUBSTITUTE(SUBSTITUTE(SUBSTITUTE(SUBSTITUTE(SUBSTITUTE(SUBSTITUTE(SUBSTITUTE(SUBSTITUTE(LOWER(TRIM(B13))," ",""),"'",""),"’",""),"·",""),"/",""),"-",""),"(",""),")",""),"（",""),"）",""),"ü","v"),";","|"),"；","|"),",","|"),"，","|"),"、","|")) | G13: =SUBSTITUTE(SUBSTITUTE(SUBSTITUTE(SUBSTITUTE(SUBSTITUTE(SUBSTITUTE(SUBSTITUTE(SUBSTITUTE(SUBSTITUTE(SUBSTITUTE(SUBSTITUTE(SUBSTITUTE(SUBSTITUTE(SUBSTITUTE(SUBSTITUTE(SUBSTITUTE(SUBSTITUTE(SUBSTITUTE(SUBSTITUTE(SUBSTITUTE(SUBSTITUTE(SUBSTITUTE(SUBSTITUTE(SUBSTITUTE(F13,"ā","a"),"á","a"),"ǎ","a"),"à","a"),"ē","e"),"é","e"),"ě","e"),"è","e"),"ī","i"),"í","i"),"ǐ","i"),"ì","i"),"ō","o"),"ó","o"),"ǒ","o"),"ò","o"),"ū","u"),"ú","u"),"ǔ","u"),"ù","u"),"ǖ","v"),"ǘ","v"),"ǚ","v"),"ǜ","v")
A14: =IF(Data_HSK4!E8="","",Data_HSK4!E8) -> yên ổn; lắp đặt | C14: =IF(OR(A14="",TRIM(B14)=""),"",IF(OR(ISNUMBER(FIND("|"&F14&"|",Data_HSK4!G8)),AND(F14=G14,ISNUMBER(FIND("|"&G14&"|",Data_HSK4!H8)))),"✅","❌")) | D14: =IF(OR(A14="",$D$5<>"Có"),"",Data_HSK4!B8&" ("&Data_HSK4!C8&")") | F14: =IF(TRIM(B14)="","",SUBSTITUTE(SUBSTITUTE(SUBSTITUTE(SUBSTITUTE(SUBSTITUTE(SUBSTITUTE(SUBSTITUTE(SUBSTITUTE(SUBSTITUTE(SUBSTITUTE(SUBSTITUTE(SUBSTITUTE(SUBSTITUTE(SUBSTITUTE(SUBSTITUTE(SUBSTITUTE(LOWER(TRIM(B14))," ",""),"'",""),"’",""),"·",""),"/",""),"-",""),"(",""),")",""),"（",""),"）",""),"ü","v"),";","|"),"；","|"),",","|"),"，","|"),"、","|")) | G14: =SUBSTITUTE(SUBSTITUTE(SUBSTITUTE(SUBSTITUTE(SUBSTITUTE(SUBSTITUTE(SUBSTITUTE(SUBSTITUTE(SUBSTITUTE(SUBSTITUTE(SUBSTITUTE(SUBSTITUTE(SUBSTITUTE(SUBSTITUTE(SUBSTITUTE(SUBSTITUTE(SUBSTITUTE(SUBSTITUTE(SUBSTITUTE(SUBSTITUTE(SUBSTITUTE(SUBSTITUTE(SUBSTITUTE(SUBSTITUTE(F14,"ā","a"),"á","a"),"ǎ","a"),"à","a"),"ē","e"),"é","e"),"ě","e"),"è","e"),"ī","i"),"í","i"),"ǐ","i"),"ì","i"),"ō","o"),"ó","o"),"ǒ","o"),"ò","o"),"ū","u"),"ú","u"),"ǔ","u"),"ù","u"),"ǖ","v"),"ǘ","v"),"ǚ","v"),"ǜ","v")
A15: =IF(Data_HSK4!E9="","",Data_HSK4!E9) -> bố trí, sắp xếp | C15: =IF(OR(A15="",TRIM(B15)=""),"",IF(OR(ISNUMBER(FIND("|"&F15&"|",Data_HSK4!G9)),AND(F15=G15,ISNUMBER(FIND("|"&G15&"|",Data_HSK4!H9)))),"✅","❌")) | D15: =IF(OR(A15="",$D$5<>"Có"),"",Data_HSK4!B9&" ("&Data_HSK4!C9&")") | F15: =IF(TRIM(B15)="","",SUBSTITUTE(SUBSTITUTE(SUBSTITUTE(SUBSTITUTE(SUBSTITUTE(SUBSTITUTE(SUBSTITUTE(SUBSTITUTE(SUBSTITUTE(SUBSTITUTE(SUBSTITUTE(SUBSTITUTE(SUBSTITUTE(SUBSTITUTE(SUBSTITUTE(SUBSTITUTE(LOWER(TRIM(B15))," ",""),"'",""),"’",""),"·",""),"/",""),"-",""),"(",""),")",""),"（",""),"）",""),"ü","v"),";","|"),"；","|"),",","|"),"，","|"),"、","|")) | G15: =SUBSTITUTE(SUBSTITUTE(SUBSTITUTE(SUBSTITUTE(SUBSTITUTE(SUBSTITUTE(SUBSTITUTE(SUBSTITUTE(SUBSTITUTE(SUBSTITUTE(SUBSTITUTE(SUBSTITUTE(SUBSTITUTE(SUBSTITUTE(SUBSTITUTE(SUBSTITUTE(SUBSTITUTE(SUBSTITUTE(SUBSTITUTE(SUBSTITUTE(SUBSTITUTE(SUBSTITUTE(SUBSTITUTE(SUBSTITUTE(F15,"ā","a"),"á","a"),"ǎ","a"),"à","a"),"ē","e"),"é","e"),"ě","e"),"è","e"),"ī","i"),"í","i"),"ǐ","i"),"ì","i"),"ō","o"),"ó","o"),"ǒ","o"),"ò","o"),"ū","u"),"ú","u"),"ǔ","u"),"ù","u"),"ǖ","v"),"ǘ","v"),"ǚ","v"),"ǜ","v")
A16: =IF(Data_HSK4!E10="","",Data_HSK4!E10) -> đúng giờ | C16: =IF(OR(A16="",TRIM(B16)=""),"",IF(OR(ISNUMBER(FIND("|"&F16&"|",Data_HSK4!G10)),AND(F16=G16,ISNUMBER(FIND("|"&G16&"|",Data_HSK4!H10)))),"✅","❌")) | D16: =IF(OR(A16="",$D$5<>"Có"),"",Data_HSK4!B10&" ("&Data_HSK4!C10&")") | F16: =IF(TRIM(B16)="","",SUBSTITUTE(SUBSTITUTE(SUBSTITUTE(SUBSTITUTE(SUBSTITUTE(SUBSTITUTE(SUBSTITUTE(SUBSTITUTE(SUBSTITUTE(SUBSTITUTE(SUBSTITUTE(SUBSTITUTE(SUBSTITUTE(SUBSTITUTE(SUBSTITUTE(SUBSTITUTE(LOWER(TRIM(B16))," ",""),"'",""),"’",""),"·",""),"/",""),"-",""),"(",""),")",""),"（",""),"）",""),"ü","v"),";","|"),"；","|"),",","|"),"，","|"),"、","|")) | G16: =SUBSTITUTE(SUBSTITUTE(SUBSTITUTE(SUBSTITUTE(SUBSTITUTE(SUBSTITUTE(SUBSTITUTE(SUBSTITUTE(SUBSTITUTE(SUBSTITUTE(SUBSTITUTE(SUBSTITUTE(SUBSTITUTE(SUBSTITUTE(SUBSTITUTE(SUBSTITUTE(SUBSTITUTE(SUBSTITUTE(SUBSTITUTE(SUBSTITUTE(SUBSTITUTE(SUBSTITUTE(SUBSTITUTE(SUBSTITUTE(F16,"ā","a"),"á","a"),"ǎ","a"),"à","a"),"ē","e"),"é","e"),"ě","e"),"è","e"),"ī","i"),"í","i"),"ǐ","i"),"ì","i"),"ō","o"),"ó","o"),"ǒ","o"),"ò","o"),"ū","u"),"ú","u"),"ǔ","u"),"ù","u"),"ǖ","v"),"ǘ","v"),"ǚ","v"),"ǜ","v")
A17: =IF(Data_HSK4!E11="","",Data_HSK4!E11) -> tối | C17: =IF(OR(A17="",TRIM(B17)=""),"",IF(OR(ISNUMBER(FIND("|"&F17&"|",Data_HSK4!G11)),AND(F17=G17,ISNUMBER(FIND("|"&G17&"|",Data_HSK4!H11)))),"✅","❌")) | D17: =IF(OR(A17="",$D$5<>"Có"),"",Data_HSK4!B11&" ("&Data_HSK4!C11&")") | F17: =IF(TRIM(B17)="","",SUBSTITUTE(SUBSTITUTE(SUBSTITUTE(SUBSTITUTE(SUBSTITUTE(SUBSTITUTE(SUBSTITUTE(SUBSTITUTE(SUBSTITUTE(SUBSTITUTE(SUBSTITUTE(SUBSTITUTE(SUBSTITUTE(SUBSTITUTE(SUBSTITUTE(SUBSTITUTE(LOWER(TRIM(B17))," ",""),"'",""),"’",""),"·",""),"/",""),"-",""),"(",""),")",""),"（",""),"）",""),"ü","v"),";","|"),"；","|"),",","|"),"，","|"),"、","|")) | G17: =SUBSTITUTE(SUBSTITUTE(SUBSTITUTE(SUBSTITUTE(SUBSTITUTE(SUBSTITUTE(SUBSTITUTE(SUBSTITUTE(SUBSTITUTE(SUBSTITUTE(SUBSTITUTE(SUBSTITUTE(SUBSTITUTE(SUBSTITUTE(SUBSTITUTE(SUBSTITUTE(SUBSTITUTE(SUBSTITUTE(SUBSTITUTE(SUBSTITUTE(SUBSTITUTE(SUBSTITUTE(SUBSTITUTE(SUBSTITUTE(F17,"ā","a"),"á","a"),"ǎ","a"),"à","a"),"ē","e"),"é","e"),"ě","e"),"è","e"),"ī","i"),"í","i"),"ǐ","i"),"ì","i"),"ō","o"),"ó","o"),"ǒ","o"),"ò","o"),"ū","u"),"ú","u"),"ǔ","u"),"ù","u"),"ǖ","v"),"ǘ","v"),"ǚ","v"),"ǜ","v")
A18: =IF(Data_HSK4!E12="","",Data_HSK4!E12) -> ám chỉ, gợi ý | C18: =IF(OR(A18="",TRIM(B18)=""),"",IF(OR(ISNUMBER(FIND("|"&F18&"|",Data_HSK4!G12)),AND(F18=G18,ISNUMBER(FIND("|"&G18&"|",Data_HSK4!H12)))),"✅","❌")) | D18: =IF(OR(A18="",$D$5<>"Có"),"",Data_HSK4!B12&" ("&Data_HSK4!C12&")") | F18: =IF(TRIM(B18)="","",SUBSTITUTE(SUBSTITUTE(SUBSTITUTE(SUBSTITUTE(SUBSTITUTE(SUBSTITUTE(SUBSTITUTE(SUBSTITUTE(SUBSTITUTE(SUBSTITUTE(SUBSTITUTE(SUBSTITUTE(SUBSTITUTE(SUBSTITUTE(SUBSTITUTE(SUBSTITUTE(LOWER(TRIM(B18))," ",""),"'",""),"’",""),"·",""),"/",""),"-",""),"(",""),")",""),"（",""),"）",""),"ü","v"),";","|"),"；","|"),",","|"),"，","|"),"、","|")) | G18: =SUBSTITUTE(SUBSTITUTE(SUBSTITUTE(SUBSTITUTE(SUBSTITUTE(SUBSTITUTE(SUBSTITUTE(SUBSTITUTE(SUBSTITUTE(SUBSTITUTE(SUBSTITUTE(SUBSTITUTE(SUBSTITUTE(SUBSTITUTE(SUBSTITUTE(SUBSTITUTE(SUBSTITUTE(SUBSTITUTE(SUBSTITUTE(SUBSTITUTE(SUBSTITUTE(SUBSTITUTE(SUBSTITUTE(SUBSTITUTE(F18,"ā","a"),"á","a"),"ǎ","a"),"à","a"),"ē","e"),"é","e"),"ě","e"),"è","e"),"ī","i"),"í","i"),"ǐ","i"),"ì","i"),"ō","o"),"ó","o"),"ǒ","o"),"ò","o"),"ū","u"),"ú","u"),"ǔ","u"),"ù","u"),"ǖ","v"),"ǘ","v"),"ǚ","v"),"ǜ","v")
A19: =IF(Data_HSK4!E13="","",Data_HSK4!E13) -> xe buýt | C19: =IF(OR(A19="",TRIM(B19)=""),"",IF(OR(ISNUMBER(FIND("|"&F19&"|",Data_HSK4!G13)),AND(F19=G19,ISNUMBER(FIND("|"&G19&"|",Data_HSK4!H13)))),"✅","❌")) | D19: =IF(OR(A19="",$D$5<>"Có"),"",Data_HSK4!B13&" ("&Data_HSK4!C13&")") | F19: =IF(TRIM(B19)="","",SUBSTITUTE(SUBSTITUTE(SUBSTITUTE(SUBSTITUTE(SUBSTITUTE(SUBSTITUTE(SUBSTITUTE(SUBSTITUTE(SUBSTITUTE(SUBSTITUTE(SUBSTITUTE(SUBSTITUTE(SUBSTITUTE(SUBSTITUTE(SUBSTITUTE(SUBSTITUTE(LOWER(TRIM(B19))," ",""),"'",""),"’",""),"·",""),"/",""),"-",""),"(",""),")",""),"（",""),"）",""),"ü","v"),";","|"),"；","|"),",","|"),"，","|"),"、","|")) | G19: =SUBSTITUTE(SUBSTITUTE(SUBSTITUTE(SUBSTITUTE(SUBSTITUTE(SUBSTITUTE(SUBSTITUTE(SUBSTITUTE(SUBSTITUTE(SUBSTITUTE(SUBSTITUTE(SUBSTITUTE(SUBSTITUTE(SUBSTITUTE(SUBSTITUTE(SUBSTITUTE(SUBSTITUTE(SUBSTITUTE(SUBSTITUTE(SUBSTITUTE(SUBSTITUTE(SUBSTITUTE(SUBSTITUTE(SUBSTITUTE(F19,"ā","a"),"á","a"),"ǎ","a"),"à","a"),"ē","e"),"é","e"),"ě","e"),"è","e"),"ī","i"),"í","i"),"ǐ","i"),"ì","i"),"ō","o"),"ó","o"),"ǒ","o"),"ò","o"),"ū","u"),"ú","u"),"ǔ","u"),"ù","u"),"ǖ","v"),"ǘ","v"),"ǚ","v"),"ǜ","v")
... A1207: =IF(Data_HSK4!E1201="","",Data_HSK4!E1201) | C1207: =IF(OR(A1207="",TRIM(B1207)=""),"",IF(OR(ISNUMBER(FIND("|"&F1207&"|",Data_HSK4!G1201)),AND(F1207=G1207,ISNUMBER(FIND("|"&G1207&"|",Data_HSK4!H1201)))),"✅","❌")) | D1207: =IF(OR(A1207="",$D$5<>"Có"),"",Data_HSK4!B1201&" ("&Data_HSK4!C1201&")") | F1207: =IF(TRIM(B1207)="","",SUBSTITUTE(SUBSTITUTE(SUBSTITUTE(SUBSTITUTE(SUBSTITUTE(SUBSTITUTE(SUBSTITUTE(SUBSTITUTE(SUBSTITUTE(SUBSTITUTE(SUBSTITUTE(SUBSTITUTE(SUBSTITUTE(SUBSTITUTE(SUBSTITUTE(SUBSTITUTE(LOWER(TRIM(B1207))," ",""),"'",""),"’",""),"·",""),"/",""),"-",""),"(",""),")",""),"（",""),"）",""),"ü","v"),";","|"),"；","|"),",","|"),"，","|"),"、","|")) | G1207: =SUBSTITUTE(SUBSTITUTE(SUBSTITUTE(SUBSTITUTE(SUBSTITUTE(SUBSTITUTE(SUBSTITUTE(SUBSTITUTE(SUBSTITUTE(SUBSTITUTE(SUBSTITUTE(SUBSTITUTE(SUBSTITUTE(SUBSTITUTE(SUBSTITUTE(SUBSTITUTE(SUBSTITUTE(SUBSTITUTE(SUBSTITUTE(SUBSTITUTE(SUBSTITUTE(SUBSTITUTE(SUBSTITUTE(SUBSTITUTE(F1207,"ā","a"),"á","a"),"ǎ","a"),"à","a"),"ē","e"),"é","e"),"ě","e"),"è","e"),"ī","i"),"í","i"),"ǐ","i"),"ì","i"),"ō","o"),"ó","o"),"ǒ","o"),"ò","o"),"ū","u"),"ú","u"),"ǔ","u"),"ù","u"),"ǖ","v"),"ǘ","v"),"ǚ","v"),"ǜ","v")

Sheet Từ vựng HSK1
A1: LUYỆN TẬP TỪ VỰNG HSK 1 (HSK 3.0 — 500 từ)
A2: Nhập chữ Hán giản thể hoặc Pinyin (có/không dấu thanh) vào cột B — chỉ cần sửa các ô màu vàng. | H2: Các bạn nhấn Tệp -> tạo bản sao lưu về drive cá nhân. Nếu có vấn đề các bạn comment bài viết cho mình hay với nha. Tks!
A3: Tổng số câu | B3: Số câu đã làm đúng ✅ | C3: Số câu sai ❌ | D3: Tỷ lệ hoàn thành (%)
A4: =COUNTIF($A$8:$A$707,"?*") -> 500 | B4: =COUNTIF($C$8:$C$707,"✅") -> 1 | C4: =COUNTIF($C$8:$C$707,"❌") -> 1 | D4: =IF(A4=0,0,B4/A4) -> 0.002
A5: Tiến độ | B5: =REPT("█",ROUND(D4*20,0))&REPT("░",20-ROUND(D4*20,0)) -> ░░░░░░░░░░░░░░░░░░░░ | C5: =IF(B4+C4=0,"Độ chính xác: –","Độ chính xác: "&TEXT(B4/(B4+C4),"0%")) -> Độ chính xác: 50% | D5: Không
D6: ▲ Hiện gợi ý (Có/Không)
A7: Ý nghĩa | B7: Ô người học nhập | C7: Kết quả | D7: Gợi ý | F7: norm có dấu | G7: norm không dấu
A8: =IF(Data_HSK1!E2="","",Data_HSK1!E2) -> yêu, yêu thích | B8: haha | C8: =IF(OR(A8="",TRIM(B8)=""),"",IF(OR(ISNUMBER(FIND("|"&F8&"|",Data_HSK1!G2)),AND(F8=G8,ISNUMBER(FIND("|"&G8&"|",Data_HSK1!H2)))),"✅","❌")) -> ❌ | D8: =IF(OR(A8="",$D$5<>"Có"),"",Data_HSK1!B2&" ("&Data_HSK1!C2&")") | F8: =IF(TRIM(B8)="","",SUBSTITUTE(SUBSTITUTE(SUBSTITUTE(SUBSTITUTE(SUBSTITUTE(SUBSTITUTE(SUBSTITUTE(SUBSTITUTE(SUBSTITUTE(SUBSTITUTE(SUBSTITUTE(SUBSTITUTE(SUBSTITUTE(SUBSTITUTE(SUBSTITUTE(SUBSTITUTE(LOWER(TRIM(B8))," ",""),"'",""),"’",""),"·",""),"/",""),"-",""),"(",""),")",""),"（",""),"）",""),"ü","v"),";","|"),"；","|"),",","|"),"，","|"),"、","|")) -> haha | G8: =SUBSTITUTE(SUBSTITUTE(SUBSTITUTE(SUBSTITUTE(SUBSTITUTE(SUBSTITUTE(SUBSTITUTE(SUBSTITUTE(SUBSTITUTE(SUBSTITUTE(SUBSTITUTE(SUBSTITUTE(SUBSTITUTE(SUBSTITUTE(SUBSTITUTE(SUBSTITUTE(SUBSTITUTE(SUBSTITUTE(SUBSTITUTE(SUBSTITUTE(SUBSTITUTE(SUBSTITUTE(SUBSTITUTE(SUBSTITUTE(F8,"ā","a"),"á","a"),"ǎ","a"),"à","a"),"ē","e"),"é","e"),"ě","e"),"è","e"),"ī","i"),"í","i"),"ǐ","i"),"ì","i"),"ō","o"),"ó","o"),"ǒ","o"),"ò","o"),"ū","u"),"ú","u"),"ǔ","u"),"ù","u"),"ǖ","v"),"ǘ","v"),"ǚ","v"),"ǜ","v") -> haha
A9: =IF(Data_HSK1!E3="","",Data_HSK1!E3) -> sở thích; ham thích | B9: 爱好 | C9: =IF(OR(A9="",TRIM(B9)=""),"",IF(OR(ISNUMBER(FIND("|"&F9&"|",Data_HSK1!G3)),AND(F9=G9,ISNUMBER(FIND("|"&G9&"|",Data_HSK1!H3)))),"✅","❌")) -> ✅ | D9: =IF(OR(A9="",$D$5<>"Có"),"",Data_HSK1!B3&" ("&Data_HSK1!C3&")") | F9: =IF(TRIM(B9)="","",SUBSTITUTE(SUBSTITUTE(SUBSTITUTE(SUBSTITUTE(SUBSTITUTE(SUBSTITUTE(SUBSTITUTE(SUBSTITUTE(SUBSTITUTE(SUBSTITUTE(SUBSTITUTE(SUBSTITUTE(SUBSTITUTE(SUBSTITUTE(SUBSTITUTE(SUBSTITUTE(LOWER(TRIM(B9))," ",""),"'",""),"’",""),"·",""),"/",""),"-",""),"(",""),")",""),"（",""),"）",""),"ü","v"),";","|"),"；","|"),",","|"),"，","|"),"、","|")) -> 爱好 | G9: =SUBSTITUTE(SUBSTITUTE(SUBSTITUTE(SUBSTITUTE(SUBSTITUTE(SUBSTITUTE(SUBSTITUTE(SUBSTITUTE(SUBSTITUTE(SUBSTITUTE(SUBSTITUTE(SUBSTITUTE(SUBSTITUTE(SUBSTITUTE(SUBSTITUTE(SUBSTITUTE(SUBSTITUTE(SUBSTITUTE(SUBSTITUTE(SUBSTITUTE(SUBSTITUTE(SUBSTITUTE(SUBSTITUTE(SUBSTITUTE(F9,"ā","a"),"á","a"),"ǎ","a"),"à","a"),"ē","e"),"é","e"),"ě","e"),"è","e"),"ī","i"),"í","i"),"ǐ","i"),"ì","i"),"ō","o"),"ó","o"),"ǒ","o"),"ò","o"),"ū","u"),"ú","u"),"ǔ","u"),"ù","u"),"ǖ","v"),"ǘ","v"),"ǚ","v"),"ǜ","v") -> 爱好
A10: =IF(Data_HSK1!E4="","",Data_HSK1!E4) -> số 8 (tám) | C10: =IF(OR(A10="",TRIM(B10)=""),"",IF(OR(ISNUMBER(FIND("|"&F10&"|",Data_HSK1!G4)),AND(F10=G10,ISNUMBER(FIND("|"&G10&"|",Data_HSK1!H4)))),"✅","❌")) | D10: =IF(OR(A10="",$D$5<>"Có"),"",Data_HSK1!B4&" ("&Data_HSK1!C4&")") | F10: =IF(TRIM(B10)="","",SUBSTITUTE(SUBSTITUTE(SUBSTITUTE(SUBSTITUTE(SUBSTITUTE(SUBSTITUTE(SUBSTITUTE(SUBSTITUTE(SUBSTITUTE(SUBSTITUTE(SUBSTITUTE(SUBSTITUTE(SUBSTITUTE(SUBSTITUTE(SUBSTITUTE(SUBSTITUTE(LOWER(TRIM(B10))," ",""),"'",""),"’",""),"·",""),"/",""),"-",""),"(",""),")",""),"（",""),"）",""),"ü","v"),";","|"),"；","|"),",","|"),"，","|"),"、","|")) | G10: =SUBSTITUTE(SUBSTITUTE(SUBSTITUTE(SUBSTITUTE(SUBSTITUTE(SUBSTITUTE(SUBSTITUTE(SUBSTITUTE(SUBSTITUTE(SUBSTITUTE(SUBSTITUTE(SUBSTITUTE(SUBSTITUTE(SUBSTITUTE(SUBSTITUTE(SUBSTITUTE(SUBSTITUTE(SUBSTITUTE(SUBSTITUTE(SUBSTITUTE(SUBSTITUTE(SUBSTITUTE(SUBSTITUTE(SUBSTITUTE(F10,"ā","a"),"á","a"),"ǎ","a"),"à","a"),"ē","e"),"é","e"),"ě","e"),"è","e"),"ī","i"),"í","i"),"ǐ","i"),"ì","i"),"ō","o"),"ó","o"),"ǒ","o"),"ò","o"),"ū","u"),"ú","u"),"ǔ","u"),"ù","u"),"ǖ","v"),"ǘ","v"),"ǚ","v"),"ǜ","v")
A11: =IF(Data_HSK1!E5="","",Data_HSK1!E5) -> bố | C11: =IF(OR(A11="",TRIM(B11)=""),"",IF(OR(ISNUMBER(FIND("|"&F11&"|",Data_HSK1!G5)),AND(F11=G11,ISNUMBER(FIND("|"&G11&"|",Data_HSK1!H5)))),"✅","❌")) | D11: =IF(OR(A11="",$D$5<>"Có"),"",Data_HSK1!B5&" ("&Data_HSK1!C5&")") | F11: =IF(TRIM(B11)="","",SUBSTITUTE(SUBSTITUTE(SUBSTITUTE(SUBSTITUTE(SUBSTITUTE(SUBSTITUTE(SUBSTITUTE(SUBSTITUTE(SUBSTITUTE(SUBSTITUTE(SUBSTITUTE(SUBSTITUTE(SUBSTITUTE(SUBSTITUTE(SUBSTITUTE(SUBSTITUTE(LOWER(TRIM(B11))," ",""),"'",""),"’",""),"·",""),"/",""),"-",""),"(",""),")",""),"（",""),"）",""),"ü","v"),";","|"),"；","|"),",","|"),"，","|"),"、","|")) | G11: =SUBSTITUTE(SUBSTITUTE(SUBSTITUTE(SUBSTITUTE(SUBSTITUTE(SUBSTITUTE(SUBSTITUTE(SUBSTITUTE(SUBSTITUTE(SUBSTITUTE(SUBSTITUTE(SUBSTITUTE(SUBSTITUTE(SUBSTITUTE(SUBSTITUTE(SUBSTITUTE(SUBSTITUTE(SUBSTITUTE(SUBSTITUTE(SUBSTITUTE(SUBSTITUTE(SUBSTITUTE(SUBSTITUTE(SUBSTITUTE(F11,"ā","a"),"á","a"),"ǎ","a"),"à","a"),"ē","e"),"é","e"),"ě","e"),"è","e"),"ī","i"),"í","i"),"ǐ","i"),"ì","i"),"ō","o"),"ó","o"),"ǒ","o"),"ò","o"),"ū","u"),"ú","u"),"ǔ","u"),"ù","u"),"ǖ","v"),"ǘ","v"),"ǚ","v"),"ǜ","v")
A12: =IF(Data_HSK1!E6="","",Data_HSK1!E6) -> nhé, nhỉ, đi (trợ từ cuối câu) | C12: =IF(OR(A12="",TRIM(B12)=""),"",IF(OR(ISNUMBER(FIND("|"&F12&"|",Data_HSK1!G6)),AND(F12=G12,ISNUMBER(FIND("|"&G12&"|",Data_HSK1!H6)))),"✅","❌")) | D12: =IF(OR(A12="",$D$5<>"Có"),"",Data_HSK1!B6&" ("&Data_HSK1!C6&")") | F12: =IF(TRIM(B12)="","",SUBSTITUTE(SUBSTITUTE(SUBSTITUTE(SUBSTITUTE(SUBSTITUTE(SUBSTITUTE(SUBSTITUTE(SUBSTITUTE(SUBSTITUTE(SUBSTITUTE(SUBSTITUTE(SUBSTITUTE(SUBSTITUTE(SUBSTITUTE(SUBSTITUTE(SUBSTITUTE(LOWER(TRIM(B12))," ",""),"'",""),"’",""),"·",""),"/",""),"-",""),"(",""),")",""),"（",""),"）",""),"ü","v"),";","|"),"；","|"),",","|"),"，","|"),"、","|")) | G12: =SUBSTITUTE(SUBSTITUTE(SUBSTITUTE(SUBSTITUTE(SUBSTITUTE(SUBSTITUTE(SUBSTITUTE(SUBSTITUTE(SUBSTITUTE(SUBSTITUTE(SUBSTITUTE(SUBSTITUTE(SUBSTITUTE(SUBSTITUTE(SUBSTITUTE(SUBSTITUTE(SUBSTITUTE(SUBSTITUTE(SUBSTITUTE(SUBSTITUTE(SUBSTITUTE(SUBSTITUTE(SUBSTITUTE(SUBSTITUTE(F12,"ā","a"),"á","a"),"ǎ","a"),"à","a"),"ē","e"),"é","e"),"ě","e"),"è","e"),"ī","i"),"í","i"),"ǐ","i"),"ì","i"),"ō","o"),"ó","o"),"ǒ","o"),"ò","o"),"ū","u"),"ú","u"),"ǔ","u"),"ù","u"),"ǖ","v"),"ǘ","v"),"ǚ","v"),"ǜ","v")
A13: =IF(Data_HSK1!E7="","",Data_HSK1!E7) -> trắng | C13: =IF(OR(A13="",TRIM(B13)=""),"",IF(OR(ISNUMBER(FIND("|"&F13&"|",Data_HSK1!G7)),AND(F13=G13,ISNUMBER(FIND("|"&G13&"|",Data_HSK1!H7)))),"✅","❌")) | D13: =IF(OR(A13="",$D$5<>"Có"),"",Data_HSK1!B7&" ("&Data_HSK1!C7&")") | F13: =IF(TRIM(B13)="","",SUBSTITUTE(SUBSTITUTE(SUBSTITUTE(SUBSTITUTE(SUBSTITUTE(SUBSTITUTE(SUBSTITUTE(SUBSTITUTE(SUBSTITUTE(SUBSTITUTE(SUBSTITUTE(SUBSTITUTE(SUBSTITUTE(SUBSTITUTE(SUBSTITUTE(SUBSTITUTE(LOWER(TRIM(B13))," ",""),"'",""),"’",""),"·",""),"/",""),"-",""),"(",""),")",""),"（",""),"）",""),"ü","v"),";","|"),"；","|"),",","|"),"，","|"),"、","|")) | G13: =SUBSTITUTE(SUBSTITUTE(SUBSTITUTE(SUBSTITUTE(SUBSTITUTE(SUBSTITUTE(SUBSTITUTE(SUBSTITUTE(SUBSTITUTE(SUBSTITUTE(SUBSTITUTE(SUBSTITUTE(SUBSTITUTE(SUBSTITUTE(SUBSTITUTE(SUBSTITUTE(SUBSTITUTE(SUBSTITUTE(SUBSTITUTE(SUBSTITUTE(SUBSTITUTE(SUBSTITUTE(SUBSTITUTE(SUBSTITUTE(F13,"ā","a"),"á","a"),"ǎ","a"),"à","a"),"ē","e"),"é","e"),"ě","e"),"è","e"),"ī","i"),"í","i"),"ǐ","i"),"ì","i"),"ō","o"),"ó","o"),"ǒ","o"),"ò","o"),"ū","u"),"ú","u"),"ǔ","u"),"ù","u"),"ǖ","v"),"ǘ","v"),"ǚ","v"),"ǜ","v")
A14: =IF(Data_HSK1!E8="","",Data_HSK1!E8) -> ban ngày | C14: =IF(OR(A14="",TRIM(B14)=""),"",IF(OR(ISNUMBER(FIND("|"&F14&"|",Data_HSK1!G8)),AND(F14=G14,ISNUMBER(FIND("|"&G14&"|",Data_HSK1!H8)))),"✅","❌")) | D14: =IF(OR(A14="",$D$5<>"Có"),"",Data_HSK1!B8&" ("&Data_HSK1!C8&")") | F14: =IF(TRIM(B14)="","",SUBSTITUTE(SUBSTITUTE(SUBSTITUTE(SUBSTITUTE(SUBSTITUTE(SUBSTITUTE(SUBSTITUTE(SUBSTITUTE(SUBSTITUTE(SUBSTITUTE(SUBSTITUTE(SUBSTITUTE(SUBSTITUTE(SUBSTITUTE(SUBSTITUTE(SUBSTITUTE(LOWER(TRIM(B14))," ",""),"'",""),"’",""),"·",""),"/",""),"-",""),"(",""),")",""),"（",""),"）",""),"ü","v"),";","|"),"；","|"),",","|"),"，","|"),"、","|")) | G14: =SUBSTITUTE(SUBSTITUTE(SUBSTITUTE(SUBSTITUTE(SUBSTITUTE(SUBSTITUTE(SUBSTITUTE(SUBSTITUTE(SUBSTITUTE(SUBSTITUTE(SUBSTITUTE(SUBSTITUTE(SUBSTITUTE(SUBSTITUTE(SUBSTITUTE(SUBSTITUTE(SUBSTITUTE(SUBSTITUTE(SUBSTITUTE(SUBSTITUTE(SUBSTITUTE(SUBSTITUTE(SUBSTITUTE(SUBSTITUTE(F14,"ā","a"),"á","a"),"ǎ","a"),"à","a"),"ē","e"),"é","e"),"ě","e"),"è","e"),"ī","i"),"í","i"),"ǐ","i"),"ì","i"),"ō","o"),"ó","o"),"ǒ","o"),"ò","o"),"ū","u"),"ú","u"),"ǔ","u"),"ù","u"),"ǖ","v"),"ǘ","v"),"ǚ","v"),"ǜ","v")
A15: =IF(Data_HSK1!E9="","",Data_HSK1!E9) -> trăm | C15: =IF(OR(A15="",TRIM(B15)=""),"",IF(OR(ISNUMBER(FIND("|"&F15&"|",Data_HSK1!G9)),AND(F15=G15,ISNUMBER(FIND("|"&G15&"|",Data_HSK1!H9)))),"✅","❌")) | D15: =IF(OR(A15="",$D$5<>"Có"),"",Data_HSK1!B9&" ("&Data_HSK1!C9&")") | F15: =IF(TRIM(B15)="","",SUBSTITUTE(SUBSTITUTE(SUBSTITUTE(SUBSTITUTE(SUBSTITUTE(SUBSTITUTE(SUBSTITUTE(SUBSTITUTE(SUBSTITUTE(SUBSTITUTE(SUBSTITUTE(SUBSTITUTE(SUBSTITUTE(SUBSTITUTE(SUBSTITUTE(SUBSTITUTE(LOWER(TRIM(B15))," ",""),"'",""),"’",""),"·",""),"/",""),"-",""),"(",""),")",""),"（",""),"）",""),"ü","v"),";","|"),"；","|"),",","|"),"，","|"),"、","|")) | G15: =SUBSTITUTE(SUBSTITUTE(SUBSTITUTE(SUBSTITUTE(SUBSTITUTE(SUBSTITUTE(SUBSTITUTE(SUBSTITUTE(SUBSTITUTE(SUBSTITUTE(SUBSTITUTE(SUBSTITUTE(SUBSTITUTE(SUBSTITUTE(SUBSTITUTE(SUBSTITUTE(SUBSTITUTE(SUBSTITUTE(SUBSTITUTE(SUBSTITUTE(SUBSTITUTE(SUBSTITUTE(SUBSTITUTE(SUBSTITUTE(F15,"ā","a"),"á","a"),"ǎ","a"),"à","a"),"ē","e"),"é","e"),"ě","e"),"è","e"),"ī","i"),"í","i"),"ǐ","i"),"ì","i"),"ō","o"),"ó","o"),"ǒ","o"),"ò","o"),"ū","u"),"ú","u"),"ǔ","u"),"ù","u"),"ǖ","v"),"ǘ","v"),"ǚ","v"),"ǜ","v")
A16: =IF(Data_HSK1!E10="","",Data_HSK1!E10) -> lớp học; ca (làm việc) | C16: =IF(OR(A16="",TRIM(B16)=""),"",IF(OR(ISNUMBER(FIND("|"&F16&"|",Data_HSK1!G10)),AND(F16=G16,ISNUMBER(FIND("|"&G16&"|",Data_HSK1!H10)))),"✅","❌")) | D16: =IF(OR(A16="",$D$5<>"Có"),"",Data_HSK1!B10&" ("&Data_HSK1!C10&")") | F16: =IF(TRIM(B16)="","",SUBSTITUTE(SUBSTITUTE(SUBSTITUTE(SUBSTITUTE(SUBSTITUTE(SUBSTITUTE(SUBSTITUTE(SUBSTITUTE(SUBSTITUTE(SUBSTITUTE(SUBSTITUTE(SUBSTITUTE(SUBSTITUTE(SUBSTITUTE(SUBSTITUTE(SUBSTITUTE(LOWER(TRIM(B16))," ",""),"'",""),"’",""),"·",""),"/",""),"-",""),"(",""),")",""),"（",""),"）",""),"ü","v"),";","|"),"；","|"),",","|"),"，","|"),"、","|")) | G16: =SUBSTITUTE(SUBSTITUTE(SUBSTITUTE(SUBSTITUTE(SUBSTITUTE(SUBSTITUTE(SUBSTITUTE(SUBSTITUTE(SUBSTITUTE(SUBSTITUTE(SUBSTITUTE(SUBSTITUTE(SUBSTITUTE(SUBSTITUTE(SUBSTITUTE(SUBSTITUTE(SUBSTITUTE(SUBSTITUTE(SUBSTITUTE(SUBSTITUTE(SUBSTITUTE(SUBSTITUTE(SUBSTITUTE(SUBSTITUTE(F16,"ā","a"),"á","a"),"ǎ","a"),"à","a"),"ē","e"),"é","e"),"ě","e"),"è","e"),"ī","i"),"í","i"),"ǐ","i"),"ì","i"),"ō","o"),"ó","o"),"ǒ","o"),"ò","o"),"ū","u"),"ú","u"),"ǔ","u"),"ù","u"),"ǖ","v"),"ǘ","v"),"ǚ","v"),"ǜ","v")
A17: =IF(Data_HSK1!E11="","",Data_HSK1!E11) -> một nửa | C17: =IF(OR(A17="",TRIM(B17)=""),"",IF(OR(ISNUMBER(FIND("|"&F17&"|",Data_HSK1!G11)),AND(F17=G17,ISNUMBER(FIND("|"&G17&"|",Data_HSK1!H11)))),"✅","❌")) | D17: =IF(OR(A17="",$D$5<>"Có"),"",Data_HSK1!B11&" ("&Data_HSK1!C11&")") | F17: =IF(TRIM(B17)="","",SUBSTITUTE(SUBSTITUTE(SUBSTITUTE(SUBSTITUTE(SUBSTITUTE(SUBSTITUTE(SUBSTITUTE(SUBSTITUTE(SUBSTITUTE(SUBSTITUTE(SUBSTITUTE(SUBSTITUTE(SUBSTITUTE(SUBSTITUTE(SUBSTITUTE(SUBSTITUTE(LOWER(TRIM(B17))," ",""),"'",""),"’",""),"·",""),"/",""),"-",""),"(",""),")",""),"（",""),"）",""),"ü","v"),";","|"),"；","|"),",","|"),"，","|"),"、","|")) | G17: =SUBSTITUTE(SUBSTITUTE(SUBSTITUTE(SUBSTITUTE(SUBSTITUTE(SUBSTITUTE(SUBSTITUTE(SUBSTITUTE(SUBSTITUTE(SUBSTITUTE(SUBSTITUTE(SUBSTITUTE(SUBSTITUTE(SUBSTITUTE(SUBSTITUTE(SUBSTITUTE(SUBSTITUTE(SUBSTITUTE(SUBSTITUTE(SUBSTITUTE(SUBSTITUTE(SUBSTITUTE(SUBSTITUTE(SUBSTITUTE(F17,"ā","a"),"á","a"),"ǎ","a"),"à","a"),"ē","e"),"é","e"),"ě","e"),"è","e"),"ī","i"),"í","i"),"ǐ","i"),"ì","i"),"ō","o"),"ó","o"),"ǒ","o"),"ò","o"),"ū","u"),"ú","u"),"ǔ","u"),"ù","u"),"ǖ","v"),"ǘ","v"),"ǚ","v"),"ǜ","v")
A18: =IF(Data_HSK1!E12="","",Data_HSK1!E12) -> nửa năm | C18: =IF(OR(A18="",TRIM(B18)=""),"",IF(OR(ISNUMBER(FIND("|"&F18&"|",Data_HSK1!G12)),AND(F18=G18,ISNUMBER(FIND("|"&G18&"|",Data_HSK1!H12)))),"✅","❌")) | D18: =IF(OR(A18="",$D$5<>"Có"),"",Data_HSK1!B12&" ("&Data_HSK1!C12&")") | F18: =IF(TRIM(B18)="","",SUBSTITUTE(SUBSTITUTE(SUBSTITUTE(SUBSTITUTE(SUBSTITUTE(SUBSTITUTE(SUBSTITUTE(SUBSTITUTE(SUBSTITUTE(SUBSTITUTE(SUBSTITUTE(SUBSTITUTE(SUBSTITUTE(SUBSTITUTE(SUBSTITUTE(SUBSTITUTE(LOWER(TRIM(B18))," ",""),"'",""),"’",""),"·",""),"/",""),"-",""),"(",""),")",""),"（",""),"）",""),"ü","v"),";","|"),"；","|"),",","|"),"，","|"),"、","|")) | G18: =SUBSTITUTE(SUBSTITUTE(SUBSTITUTE(SUBSTITUTE(SUBSTITUTE(SUBSTITUTE(SUBSTITUTE(SUBSTITUTE(SUBSTITUTE(SUBSTITUTE(SUBSTITUTE(SUBSTITUTE(SUBSTITUTE(SUBSTITUTE(SUBSTITUTE(SUBSTITUTE(SUBSTITUTE(SUBSTITUTE(SUBSTITUTE(SUBSTITUTE(SUBSTITUTE(SUBSTITUTE(SUBSTITUTE(SUBSTITUTE(F18,"ā","a"),"á","a"),"ǎ","a"),"à","a"),"ē","e"),"é","e"),"ě","e"),"è","e"),"ī","i"),"í","i"),"ǐ","i"),"ì","i"),"ō","o"),"ó","o"),"ǒ","o"),"ò","o"),"ū","u"),"ú","u"),"ǔ","u"),"ù","u"),"ǖ","v"),"ǘ","v"),"ǚ","v"),"ǜ","v")
